Workbook

Sheet Guide Sheet
A1: PyPSA Model Notebook
A2: Todo va en minúsculas y separado por un guión bajo
B3: p_nom | C3: MW
B4: Demandas | C4: MWh
B5: capital_cost | C5: euros
B6: marginal_cost | C6: euros
B7: ramp_limit_up
B8: ramp_limit_down
B9: e_nom | C9: MWh
B10: e_initial
B11: e_min_pu
B12: e_max_pu

Sheet carriers
A1: name | B1: overwrite
A2: AC | B2: true
A3: water | B3: true
A4: wind | B4: true
A5: gas | B5: true
A6: solar_pv | B6: true
A7: solar_csp | B7: true
A8: solar_rooftop | B8: true
A9: grid_import | B9: true
A10: biomass | B10: true
A11: hydrogen | B11: true
A12: load_shedding | B12: true
... A19: extragenerator | B19: true

Sheet buses_2busSRES
A1: name | B1: carrier | C1: overwrite | D1: x | E1: y
A2: ES_electricity_market_bus | B2: AC | C2: true | D2: -3.7038 | E2: 40.4168
A3: ES_water_bus | B3: water | C3: true | D3: -3.7038 | E3: 40.4168
A4: ES_gas_bus | B4: gas | C4: true | D4: -3.7038 | E4: 40.4168
A5: ES_hydrogen_bus | B5: hydrogen | C5: true | D5: -3.7038 | E5: 40.4168
A6: ES_SRES_excedentes_bus | B6: AC | C6: true | D6: -3.7038 | E6: 40.4168
A7: ES_SRES_electrolyzer_bus | B7: hydrogen | C7: true | D7: -3.7038 | E7: 40.4168
A8: PT_electricity_market_bus | B8: AC | C8: true | D8: -9.1393 | E8: 38.7223
A9: PT_water_bus | B9: water | C9: true | D9: -9.1393 | E9: 38.7223
A10: PT_gas_bus | B10: gas | C10: true | D10: -9.1393 | E10: 38.7223
A11: PT_hydrogen_bus | B11: hydrogen | C11: true | D11: -9.1393 | E11: 38.7223
A12: PT_SRES_excedentes_bus | B12: AC | C12: true | D12: -9.1393 | E12: 38.7223
A13: PT_SRES_electrolyzer_bus | B13: hydrogen | C13: true | D13: -9.1393 | E13: 38.7223
... A19: EU_hydrogen_bus | B19: hydrogen | C19: true | D19: 6.3522 | E19: 50.8566

Sheet generators_2busSRES
A1: name | B1: bus | C1: p_nom | D1: marginal_cost | E1: carrier | F1: overwrite
A2: ES_solar_pv | B2: ES_electricity_market_bus | C2: 83000 | D2: 0 | E2: solar_pv | F2: true
A3: ES_solar_csp | B3: ES_electricity_market_bus | C3: 4805 | D3: 0 | E3: solar_csp | F3: true
A4: ES_wind | B4: ES_electricity_market_bus | C4: 91799.794 | D4: 0 | E4: wind | F4: true
A5: ES_biomass | B5: ES_electricity_market_bus | C5: =2462.66 -> 2462.66 | D5: 2 | E5: biomass | F5: true
A6: ES_gas | B6: ES_gas_bus | C6: =10000000000000 -> 10000000000000 | D6: 0 | E6: gas | F6: true
A7: ES_water | B7: ES_electricity_market_bus | C7: 3117.9191 | D7: 0 | E7: water | F7: true
A8: ES_reservoir | B8: ES_electricity_market_bus | C8: 11536.3 | D8: 10 | E8: reservoir | F8: true
A9: ES_extragenerator | B9: ES_electricity_market_bus | C9: 8980 | D9: 8 | E9: extragenerator | F9: true
A10: ES_SRES_excedentes | B10: ES_SRES_excedentes_bus | C10: 32600 | D10: 0 | E10: sres_excedentes | F10: true
A11: ES_SRES_electrolyzer | B11: ES_SRES_electrolyzer_bus | C11: =(37999*2)-C10 -> 43398 | D11: 0 | E11: sres_electrolyzer | F11: true
A12: PT_solar_pv | B12: PT_electricity_market_bus | C12: 14378.2 | D12: 0 | E12: solar_pv | F12: true
A13: PT_wind_onshore | B13: PT_electricity_market_bus | C13: 11643.6 | D13: 0 | E13: wind_onshore | F13: true
A14: PT_wind_offshore | B14: PT_electricity_market_bus | C14: 646 | D14: 0 | E14: wind_offshore | F14: true
A15: PT_biomass | B15: PT_electricity_market_bus | C15: 1607 | D15: 2 | E15: biomass | F15: true
A16: PT_gas | B16: PT_gas_bus | C16: =10000000000000 -> 10000000000000 | D16: 0 | E16: gas | F16: true
A17: PT_water | B17: PT_electricity_market_bus | C17: =508.3+278 -> 786.3 | D17: 0 | E17: water | F17: true
A18: PT_reservoir | B18: PT_electricity_market_bus | C18: 3135.5 | D18: 10 | E18: reservoir | F18: true
A19: PT_extragenerator | B19: PT_electricity_market_bus | C19: 2557 | D19: 8 | E19: extragenerator | F19: true
A20: PT_SRES_excedentes | B20: PT_SRES_excedentes_bus | C20: 13478 | D20: 0 | E20: sres_excedentes | F20: true
A21: PT_SRES_electrolyzer | B21: PT_SRES_electrolyzer_bus | C21: =22506.9-C20 -> 9028.9 | D21: 0 | E21: sres_electrolyzer | F21: true
A22: ES_load_shedding | B22: ES_electricity_market_bus | C22: 10000000 | D22: 10000 | E22: load_shedding | F22: true
A23: PT_load_shedding | B23: PT_electricity_market_bus | C23: 10000000 | D23: 10000 | E23: load_shedding | F23: true
A24: FR_load_shedding | B24: FR_electricity_market_bus | C24: 10000000 | D24: 10000 | E24: load_shedding | F24: true
A25: ES_load_shedding_h2 | B25: ES_hydrogen_bus | C25: 10000000 | D25: 2500 | E25: load_shedding | F25: true
A26: PT_load_shedding_h2 | B26: PT_hydrogen_bus | C26: 10000000 | D26: 2500 | E26: load_shedding | F26: true
A27: FR_load_shedding_h2 | B27: FR_hydrogen_bus | C27: 10000000 | D27: 2500 | E27: load_shedding | F27: true
A28: FRS_load_shedding_h2 | B28: FRS_hydrogen_bus | C28: 10000000 | D28: 2500 | E28: load_shedding | F28: true
A29: FRSW_load_shedding_h2 | B29: FRSW_hydrogen_bus | C29: 10000000 | D29: 2500 | E29: load_shedding | F29: true
A30: FR_electricity_generator | B30: FR_electricity_market_bus | C30: 5000 | D30: 15.63 | E30: AC | F30: true
A31: FR_hydrogen_generator_FRSW | B31: FRSW_hydrogen_bus | C31: 1553.6723 | D31: 0 | E31: hydrogen | F31: true
A32: FR_hydrogen_generator_FRH2 | B32: FR_hydrogen_bus | C32: 6779.661 | D32: 0 | E32: hydrogen | F32: true
A33: FR_hydrogen_generator_FRh2_plus | B33: FR_hydrogen_bus | C33: 6779.661 | D33: 0 | E33: hydrogen | F33: true
A34: MA_h2lowband | B34: MA_hydrogen_bus | C34: 1517.8 | D34: 0 | E34: hydrogen | F34: true
A35: MA_h2highband | B35: MA_hydrogen_bus | C35: =3000-C34 -> 1482.2 | D35: =73.7 -> 73.7 | E35: hydrogen | F35: true
A36: EU_hydrogen_generator | B36: EU_hydrogen_bus | C36: 10116.525 | D36: 0 | E36: hydrogen | F36: true

Sheet links_2busSRES
A1: name | B1: bus0 | C1: bus1 | D1: p_nom | E1: p_min_pu | F1: efficiency | G1: marginal_cost | H1: carrier | I1: overwrite
A2: ES_CCGT | B2: ES_gas_bus | C2: ES_electricity_market_bus | D2: 28766.678 | F2: 1 | G2: 146.19 | H2: gas | I2: true
A3: ES_turbina | B3: ES_water_bus | C3: ES_electricity_market_bus | D3: 13603.98 | F3: 1 | G3: 0 | H3: water | I3: true
A4: ES_pump | B4: ES_electricity_market_bus | C4: ES_water_bus | D4: 13320.75 | F4: 1 | G4: 0 | H4: AC | I4: true
A5: ES_electrolyzer | B5: ES_electricity_market_bus | C5: ES_hydrogen_bus | D5: 15500 | F5: 1 | G5: 0 | H5: hydrogen | I5: true
A6: ES_SRES_electrolyzer | B6: ES_SRES_electrolyzer_bus | C6: ES_hydrogen_bus | D6: =32600 -> 32600 | F6: 0.7 | G6: 0.1 | H6: hydrogen | I6: true
A7: ES_SRES_excedentes | B7: ES_SRES_excedentes_bus | C7: ES_electricity_market_bus | D7: 100000 | F7: 1 | G7: 0 | H7: AC | I7: true
A8: PT_CCGT | B8: PT_gas_bus | C8: PT_electricity_market_bus | D8: =1357+468.996 -> 1825.996 | F8: 1 | G8: 146.19 | H8: gas | I8: true
A9: PT_turbina | B9: PT_water_bus | C9: PT_electricity_market_bus | D9: 4613 | F9: 1 | G9: 0 | H9: water | I9: true
A10: PT_pump | B10: PT_electricity_market_bus | C10: PT_water_bus | D10: 3837 | F10: 1 | G10: 0 | H10: AC | I10: true
A11: PT_electrolyzer | B11: PT_electricity_market_bus | C11: PT_hydrogen_bus | D11: 0 | F11: 0.7 | G11: 0 | H11: hydrogen | I11: true
A12: PT_SRES_electrolyzer | B12: PT_SRES_electrolyzer_bus | C12: PT_hydrogen_bus | D12: =13478 -> 13478 | F12: 0.7 | G12: 0 | H12: hydrogen | I12: true
A13: PT_SRES_excedentes | B13: PT_SRES_excedentes_bus | C13: PT_electricity_market_bus | D13: 100000 | F13: 1 | G13: 0 | H13: AC | I13: true
A14: ES_PT_interconexion_electricidad | B14: ES_electricity_market_bus | C14: PT_electricity_market_bus | D14: 4200 | F14: 1 | G14: 2 | H14: AC | I14: true
A15: ES_PT_interconexion_hidrogeno | B15: ES_hydrogen_bus | C15: PT_hydrogen_bus | D15: 2860.1695 | F15: 1 | G15: 0.01 | H15: hydrogen | I15: true
A16: PT_ES_interconexion_electricidad | B16: PT_electricity_market_bus | C16: ES_electricity_market_bus | D16: 3500 | F16: 1 | G16: 2 | H16: AC | I16: true
A17: PT_ES_interconexion_hidrogeno | B17: PT_hydrogen_bus | C17: ES_hydrogen_bus | D17: 2860.1695 | F17: 1 | G17: 0 | H17: hydrogen | I17: true
A18: ES_FR_interconexion_electricidad | B18: ES_electricity_market_bus | C18: FR_electricity_market_bus | D18: 5001 | F18: 1 | G18: 2 | H18: AC | I18: true
A19: FR_ES_interconexion_electricidad | B19: FR_electricity_market_bus | C19: ES_electricity_market_bus | D19: 5001 | F19: 1 | G19: 2 | H19: AC | I19: true
A20: ES_FR_interconexion_hidrogeno_IrunLarrau | B20: ES_hydrogen_bus | C20: FRSW_hydrogen_bus | D20: 5014.1243 | F20: 1 | G20: 0.01 | H20: hydrogen | I20: true
A21: ES_FR_interconexion_hidrogeno_BarMar | B21: ES_hydrogen_bus | C21: FRS_hydrogen_bus | D21: 7627.1186 | F21: 1 | G21: 0.01 | H21: hydrogen | I21: true
A22: FR_ES_interconexion_hidrogeno_BarMar | B22: FRS_hydrogen_bus | C22: ES_hydrogen_bus | D22: 7627.1186 | F22: 1 | G22: 0.01 | H22: hydrogen | I22: true
A23: FR_FR_interconexion_hidrogeno_SWtoS | B23: FRSW_hydrogen_bus | C23: FRS_hydrogen_bus | D23: 1553.6723 | F23: 1 | G23: 0.01 | H23: hydrogen | I23: true
A24: FR_FR_interconexion_hidrogeno_StoFRh2 | B24: FRS_hydrogen_bus | C24: FR_hydrogen_bus | D24: 6780.661 | F24: 1 | G24: 0.01 | H24: hydrogen | I24: true
A25: FR_FR_interconexion_hidrogeno_FRh2toS | B25: FR_hydrogen_bus | C25: FRS_hydrogen_bus | D25: 6780.661 | F25: 1 | G25: 0.01 | H25: hydrogen | I25: true
A26: MA_ES_interconexion_hidrogeno | B26: MA_hydrogen_bus | C26: ES_hydrogen_bus | D26: 3742.94 | E26: 0.4 | F26: 1 | G26: 0.01 | H26: hydrogen | I26: true
A27: EU_FR_hidrogeno | B27: EU_hydrogen_bus | C27: FR_hydrogen_bus | D27: 10000 | F27: 1 | G27: 0.001 | H27: hydrogen | I27: true
A28: FR_EU_hidrogeno | B28: FR_hydrogen_bus | C28: EU_hydrogen_bus | D28: 10116.525 | F28: 1 | G28: 0.001 | H28: hydrogen | I28: true

Sheet loads
A1: name | B1: bus | C1: carrier | D1: overwrite
A2: ES_demand_2040 | B2: ES_electricity_market_bus | C2: AC | D2: true
A3: ES_hydrogen_demand | B3: ES_hydrogen_bus | C3: hydrogen | D3: true
A4: PT_demand_2040 | B4: PT_electricity_market_bus | C4: AC | D4: true
A5: PT_hydrogen_demand | B5: PT_hydrogen_bus | C5: hydrogen | D5: true
A6: FR_demand_2040 | B6: FR_electricity_market_bus | C6: AC | D6: true
A7: FR_hydrogen_demand | B7: FR_hydrogen_bus | C7: hydrogen | D7: true
A8: EU_hydrogen_demand | B8: EU_hydrogen_bus | C8: hydrogen | D8: true

Sheet run_of_river_inflow
A1: hora | B1: ES_hydraulic_profile | C1: PT_hydraulic_profile | D1: FR_hydraulic_profile
A2: =0 -> 0 | B2: 0.25493919 | C2: 0.46568963 | D2: 0.50275862
A3: =A2+1 -> 1 | B3: 0.25493919 | C3: 0.81843675 | D3: 0.50275862
A4: =A3+1 -> 2 | B4: 0.25493919 | C4: 0.46568963 | D4: 0.50275862
A5: =A4+1 -> 3 | B5: 0.25493919 | C5: 0.81843675 | D5: 0.50275862
A6: =A5+1 -> 4 | B6: 0.25493919 | C6: 0.46568963 | D6: 0.50275862
A7: =A6+1 -> 5 | B7: 0.25493919 | C7: 0.81843675 | D7: 0.50275862
A8: =A7+1 -> 6 | B8: 0.25493919 | C8: 0.46568963 | D8: 0.50275862
A9: =A8+1 -> 7 | B9: 0.25493919 | C9: 0.46568963 | D9: 0.50275862
A10: =A9+1 -> 8 | B10: 0.25493919 | C10: 0.81843675 | D10: 0.50275862
A11: =A10+1 -> 9 | B11: 0.25493919 | C11: 0.6612232 | D11: 0.50275862
A12: =A11+1 -> 10 | B12: 0.25493919 | C12: 0.46568963 | D12: 0.50275862
A13: =A12+1 -> 11 | B13: 0.25493919 | C13: 0.46568963 | D13: 0.50275862
A14: =A13+1 -> 12 | B14: 0.25493919 | C14: 0.46568963 | D14: 0.50275862
... A169: =A168+1 -> 167 | B169: 0.25493919 | C169: 0.81843675 | D169: 0.50275862

Sheet store
A1: name | B1: bus | C1: e_nom | D1: e_initial | E1: e_min_pu | F1: e_max_pu | G1: cyclic_state_of_charge | H1: marginal_cost | I1: carrier | J1: overwrite
A2: ES_embalse | B2: ES_water_bus | C2: =20414989 -> 20414989 | D2: =C2*F2 -> 18373490 | E2: 0.2 | F2: 0.9 | G2: false | H2: 1 | I2: water | J2: true
A3: PT_embalse | B3: PT_water_bus | C3: =3307600 -> 3307600 | D3: =C3*F3 -> 2976840 | E3: 0.2 | F3: 0.9 | G3: false | H3: 1 | I3: water | J3: true

Sheet storage_units
A1: name | B1: bus | C1: p_nom | D1: max_hours | E1: efficiency_store | F1: efficiency_dispatch | G1: capital_cost | H1: cyclic_state_of_charge | I1: marginal_cost | J1: carrier | K1: overwrite
A2: ES_electricity_market_battery | B2: ES_electricity_market_bus | C2: =26698 -> 26698 | D2: 2 | E2: 0.89658206 | F2: 0.89658206 | H2: false | I2: 0.1 | J2: AC | K2: true
A3: ES_hydrogen_market_battery | B3: ES_hydrogen_bus | C3: 2583 | D3: 591.56 | E3: 1 | F3: 1 | H3: false | I3: 1 | J3: hydrogen | K3: true
A4: PT_electricity_market_battery | B4: PT_electricity_market_bus | C4: =3000 -> 3000 | D4: 4 | E4: 0.92 | F4: 0.92 | H4: false | I4: 0.1 | J4: AC | K4: true
A5: FRSW_hydrogen_market_battery | B5: FRSW_hydrogen_bus | C5: 330 | D5: 1609.0909 | E5: 1 | F5: 1 | H5: false | I5: 1 | J5: hydrogen | K5: true
A6: FRS_hydrogen_market_battery | B6: FRS_hydrogen_bus | C6: 1240 | D6: 479.83871 | E6: 1 | F6: 1 | H6: false | I6: 1 | J6: hydrogen | K6: true

Sheet demands
A1: ES_demand_2040 | B1: ES_hydrogen_demand | C1: PT_demand_2040 | D1: PT_hydrogen_demand | E1: FR_demand_2040 | F1: FR_hydrogen_demand | G1: EU_hydrogen_demand
A2: 38627.656 | B2: 11835.473 | C2: 9779.8592 | D2: 1194.7295 | E2: 0 | F2: 6779.661 | G2: 10116.525
A3: 42028.284 | B3: 11835.473 | C3: 8281.423 | D3: 1194.7295 | E3: 0 | F3: 6779.661 | G3: 10116.525
A4: 41474.456 | B4: 11835.473 | C4: 7831.94 | D4: 1194.7295 | E4: 0 | F4: 6779.661 | G4: 10116.525
A5: 41617.486 | B5: 11835.473 | C5: 10008.773 | D5: 1194.7295 | E5: 0 | F5: 6779.661 | G5: 10116.525
A6: 40803.821 | B6: 11851.183 | C6: 8961.4193 | D6: 1194.7295 | E6: 0 | F6: 6779.661 | G6: 10116.525
A7: 37447.756 | B7: 11882.603 | C7: 8637.9358 | D7: 1292.686 | E7: 0 | F7: 6779.661 | G7: 10116.525
A8: 36103.774 | B8: 11898.313 | C8: 7383.2223 | D8: 1390.6425 | E8: 0 | F8: 6779.661 | G8: 10116.525
A9: 39057.199 | B9: 11914.023 | C9: 7502.5396 | D9: 1483.4434 | E9: 0 | F9: 6779.661 | G9: 10116.525
A10: 39793.092 | B10: 11914.023 | C10: 7534.8562 | D10: 1581.3998 | E10: 0 | F10: 6779.661 | G10: 10116.525
A11: 38571.938 | B11: 11914.023 | C11: 8215.5817 | D11: 1581.3998 | E11: 0 | F11: 6779.661 | G11: 10116.525
A12: 37154.668 | B12: 11914.023 | C12: 10254.134 | D12: 1632.9559 | E12: 578.16101 | F12: 6779.661 | G12: 10116.525
A13: 37945.551 | B13: 11898.313 | C13: 11911.796 | D13: 1632.9559 | E13: 5000 | F13: 6779.661 | G13: 10116.525
... A169: 50085.064 | B169: 11999.059 | C169: 8903.6357 | D169: 1455.3989 | E169: 5000 | F169: 6779.661 | G169: 10116.525

Sheet profiles
A1: ES_solar_pv_profile | B1: ES_solar_csp_profile | C1: ES_wind_profile | D1: ES_biomass_profile | E1: ES_ccgt_profile | F1: ES_turbine_profile | G1: ES_pump_profile | H1: ES_reservoir_profile | I1: ES_electrolyzer_profile | J1: ES_excedentes_profile | K1: ES_generacionh2SRES | L1: PT_solar_pv_profile | M1: PT_wind_onshore_profile | N1: PT_wind_offshore_profile | O1: PT_biomass_profile | P1: PT_ccgt_profile | Q1: PT_turbine_profile | R1: PT_pump_profile | S1: PT_reservoir_profile | T1: PT_electrolyzer_profile | U1: PT_excedentes_profile | V1: PT_generacionh2SRES | W1: MA_hydrogen_profile_high | X1: MA_hydrogen_profile_low | Y1: FR00_generation | Z1: FRh2_generation | AA1: FRh2_generation+ | AB1: FRh2SW_generation | AC1: ES_extragenerator | AD1: PT_extragenerator | AE1: FR_irunlarrao | AF1: FR_precioFRh2 | AG1: EU_precio | AH1: EU_generation
A2: 0 | B2: 0 | C2: 0.27513822 | D2: 0.26900019 | E2: 0.257 | F2: 0.23203283 | G2: 0 | H2: 0.68245451 | I2: 0.32071055 | J2: 0 | K2: 0.22770449 | L2: 0 | M2: 0.119 | N2: 0.132 | O2: 0.5376117 | P2: 0.84 | Q2: 1 | R2: 0 | S2: 0.82634349 | T2: 0.1045903 | U2: 0 | V2: 0.07425911 | W2: 0.71590848 | X2: =1 -> 1 | Y2: 1 | Z2: 0 | AA2: 1 | AB2: 0.78759999 | AC2: 0 | AD2: 0 | AE2: 0 | AF2: ='Datos Modificaciones Bus Europa'!G4 -> 147.6721 | AG2: ='Datos Modificaciones Bus Europa'!F4 -> 144.7479 | AH2: 1
A3: 0 | B3: 0 | C3: 0.29443188 | D3: 0.26699991 | E3: 0.257 | F3: 0.23203283 | G3: 0.46792369 | H3: 0.68245451 | I3: 0.34319991 | J3: 0 | K3: 0.24367193 | L3: 0 | M3: 0.125 | N3: 0.118 | O3: 0.53382203 | P3: 0.84 | Q3: 1 | R3: 0 | S3: 0.82634349 | T3: 0.096099792 | U3: 0 | V3: 0.068230853 | W3: 0.71590848 | X3: =1 -> 1 | Y3: 1 | Z3: 0 | AA3: 1 | AB3: 0.78759999 | AC3: 0 | AD3: 0 | AE3: 0 | AF3: ='Datos Modificaciones Bus Europa'!G5 -> 12.1402 | AG3: ='Datos Modificaciones Bus Europa'!F5 -> 11.8998 | AH3: 1
A4: 0 | B4: 0 | C4: 0.29945538 | D4: 0.26500004 | E4: 0.257 | F4: 0.23203283 | G4: 0.17940284 | H4: 0.68245451 | I4: 0.34905549 | J4: 0 | K4: 0.2478294 | L4: 0 | M4: 0.137 | N4: 0.11 | O4: 0.53300436 | P4: 0.84 | Q4: 1 | R4: 0 | S4: 0.82634349 | T4: 0.090471212 | U4: 0 | V4: 0.064234561 | W4: 0.71590848 | X4: =1 -> 1 | Y4: 1 | Z4: 0 | AA4: 1 | AB4: 0.78759999 | AC4: 0 | AD4: 0 | AE4: 0 | AF4: ='Datos Modificaciones Bus Europa'!G6 -> 12.1402 | AG4: ='Datos Modificaciones Bus Europa'!F6 -> 11.8998 | AH4: 1
A5: 0 | B5: 0 | C5: 0.30697123 | D5: 0.2749998 | E5: 0.257 | F5: 0.23203283 | G5: 0.11157777 | H5: 0.68245451 | I5: 0.35781623 | J5: 0 | K5: 0.25404952 | L5: 0 | M5: 0.153 | N5: 0.105 | O5: 0.53906596 | P5: 0.84 | Q5: 1 | R5: 0 | S5: 0.82634349 | T5: 0.085199585 | U5: 0 | V5: 0.060491705 | W5: 0.71590848 | X5: =1 -> 1 | Y5: 1 | Z5: 0 | AA5: 1 | AB5: 0.78759999 | AC5: 0 | AD5: 0 | AE5: 0 | AF5: ='Datos Modificaciones Bus Europa'!G7 -> 12.1402 | AG5: ='Datos Modificaciones Bus Europa'!F7 -> 11.8998 | AH5: 1
A6: 0 | B6: 0 | C6: 0.32181368 | D6: 0.27899994 | E6: 0.257 | F6: 0.23203283 | G6: 0.52852217 | H6: 0.68245451 | I6: 0.37511709 | J6: 0 | K6: 0.26633313 | L6: 0 | M6: 0.167 | N6: 0.101 | O6: 0.54218046 | P6: 0.84 | Q6: 1 | R6: 0 | S6: 0.82634349 | T6: 0.081436637 | U6: 0 | V6: 0.057820013 | W6: 0.71590848 | X6: =1 -> 1 | Y6: 1 | Z6: 0 | AA6: 1 | AB6: 0.78759999 | AC6: 0 | AD6: 0 | AE6: 0 | AF6: ='Datos Modificaciones Bus Europa'!G8 -> 10.1202 | AG6: ='Datos Modificaciones Bus Europa'!F8 -> 9.9198 | AH6: 1
A7: 0 | B7: 0 | C7: 0.32374316 | D7: 0.29099998 | E7: 0.257 | F7: 0.23203283 | G7: 0.78248972 | H7: 0.68245451 | I7: 0.37736613 | J7: 0 | K7: 0.26792996 | L7: 0 | M7: 0.178 | N7: 0.097 | O7: 0.55440075 | P7: 0.84 | Q7: 1 | R7: 0 | S7: 0.82634349 | T7: 0.079330835 | U7: 0 | V7: 0.056324893 | W7: 0.71590848 | X7: =1 -> 1 | Y7: 1 | Z7: 0 | AA7: 1 | AB7: 0.78759999 | AC7: 0 | AD7: 0 | AE7: 0 | AF7: ='Datos Modificaciones Bus Europa'!G9 -> 10.1202 | AG7: ='Datos Modificaciones Bus Europa'!F9 -> 9.9198 | AH7: 1
A8: 0 | B8: 0 | C8: 0.3027346 | D8: 0.32799981 | E8: 0.257 | F8: 0.23203283 | G8: 0.6529081 | H8: 0.68245451 | I8: 0.35287785 | J8: 0 | K8: 0.25054328 | L8: 0 | M8: 0.183 | N8: 0.092 | O8: 0.56481269 | P8: 0.84 | Q8: 1 | R8: 0 | S8: 0.82634349 | T8: 0.076747292 | U8: 0 | V8: 0.054490577 | W8: 0.71590848 | X8: =1 -> 1 | Y8: 1 | Z8: 0 | AA8: 1 | AB8: 0.78759999 | AC8: 0 | AD8: 0 | AE8: 0 | AF8: ='Datos Modificaciones Bus Europa'!G10 -> 10.1202 | AG8: ='Datos Modificaciones Bus Europa'!F10 -> 9.9198 | AH8: 1
A9: 0 | B9: 0 | C9: 0.24533329 | D9: 0.35799989 | E9: 0.257 | F9: 0.23203283 | G9: 0 | H9: 0.68245451 | I9: 0.2859689 | J9: 0 | K9: 0.20303792 | L9: 0 | M9: 0.183 | N9: 0.091 | O9: 0.56885128 | P9: 0.84 | Q9: 1 | R9: 0 | S9: 0.82634349 | T9: 0.077074863 | U9: 0 | V9: 0.054723153 | W9: 0.71590848 | X9: =1 -> 1 | Y9: 1 | Z9: 0 | AA9: 1 | AB9: 0.78759999 | AC9: 0 | AD9: 0 | AE9: 0 | AF9: ='Datos Modificaciones Bus Europa'!G11 -> 12.1402 | AG9: ='Datos Modificaciones Bus Europa'!F11 -> 11.8998 | AH9: 1
A10: 0 | B10: 0 | C10: 0.19145564 | D10: 0.37100006 | E10: 0.257 | F10: 0.23203283 | G10: 0 | H10: 0.68245451 | I10: 0.22869706 | J10: 0 | K10: 0.16237491 | L10: 0 | M10: 0.172 | N10: 0.089 | O10: 0.56735719 | P10: 0.84 | Q10: 1 | R10: 0 | S10: 0.82634349 | T10: 0.077029604 | U10: 0 | V10: 0.054691019 | W10: 0.71590848 | X10: =1 -> 1 | Y10: 1 | Z10: 0 | AA10: 1 | AB10: 0.78759999 | AC10: 0 | AD10: 0 | AE10: 0 | AF10: ='Datos Modificaciones Bus Europa'!G12 -> 12.1402 | AG10: ='Datos Modificaciones Bus Europa'!F12 -> 11.8998 | AH10: 1
A11: 0.122 | B11: 0.071 | C11: 0.1646723 | D11: 0.39099998 | E11: 0.257 | F11: 0.23203283 | G11: 0.30477425 | H11: 0.68245451 | I11: 0.3395939 | J11: 0 | K11: 0.24111167 | L11: 0.074 | M11: 0.134 | N11: 0.089 | O11: 0.5672626 | P11: 0.84 | Q11: 1 | R11: 0 | S11: 0.82634349 | T11: 0.12732067 | U11: 0 | V11: 0.08694803 | W11: 0.71590848 | X11: =1 -> 1 | Y11: 1 | Z11: 0 | AA11: 1 | AB11: 0.78759999 | AC11: 0 | AD11: 0 | AE11: 0 | AF11: ='Datos Modificaciones Bus Europa'!G13 -> 12.1402 | AG11: ='Datos Modificaciones Bus Europa'!F13 -> 11.8998 | AH11: 1
A12: 0.313 | B12: 0.188 | C12: 0.15553496 | D12: 0.39899986 | E12: 0.257 | F12: 0 | G12: 0.78248972 | H12: 0.68245451 | I12: 0.54153374 | J12: 0 | K12: 0.38448896 | L12: 0.265 | M12: 0.072 | N12: 0.085 | O12: 0.57141879 | P12: 0.84 | Q12: 1 | R12: 0 | S12: 0.82634349 | T12: 0.26103302 | U12: 0 | V12: 0.12303024 | W12: 0.71590848 | X12: =1 -> 1 | Y12: 0 | Z12: 0 | AA12: 1 | AB12: 0.58085181 | AC12: 0.36858103 | AD12: 0.1990454 | AE12: 0.12987701 | AF12: ='Datos Modificaciones Bus Europa'!G14 -> 0.16448571 | AG12: ='Datos Modificaciones Bus Europa'!F14 -> 0.16122857 | AH12: 1
A13: 0.379 | B13: 0.31 | C13: 0.16481443 | D13: 0.40499988 | E13: 0.257 | F13: 0 | G13: 0.78248972 | H13: 0.68245451 | I13: 0.67041506 | J13: 0 | K13: 0.47599469 | L13: 0.442 | M13: 0.038 | N13: 0.082 | O13: 0.56903049 | P13: 0.84 | Q13: 0.7552577 | R13: 0 | S13: 0.82634349 | T13: 0.39263199 | U13: 0 | V13: 0.15528725 | W13: 0.71590848 | X13: =1 -> 1 | Y13: 0 | Z13: 0 | AA13: 1 | AB13: 0.3687478 | AC13: 0.60054407 | AD13: 0.60361206 | AE13: 0.18916563 | AF13: ='Datos Modificaciones Bus Europa'!G15 -> 0.16448571 | AG13: ='Datos Modificaciones Bus Europa'!F15 -> 0.16122857 | AH13: 1
... A168: 0 | B168: 0 | C168: 0.73354012 | D168: 0.37299993 | E168: 0.257 | F168: 0.6971194 | G168: 1 | H168: 0.68245451 | I168: 0.85503957 | J168: 0 | K168: 0.29351151 | L168: 0 | M168: 0.277 | N168: 0.448 | O168: 0.63864406 | P168: 0.84 | Q168: 1 | R168: 1 | S168: 0.82634349 | T168: 0.30058807 | U168: 0 | V168: 0.1079833 | W168: 1 | X168: =1 -> 1 | Y168: 0 | Z168: 0 | AA168: 1 | AB168: 0.36998878 | AC168: 0 | AD168: 0 | AE168: 0 | AF168: ='Datos Modificaciones Bus Europa'!G170 -> 0.16448571 | AG168: ='Datos Modificaciones Bus Europa'!F170 -> 0.16122857 | AH168: 1
A169: 0 | B169: 0 | C169: 0.75291925 | D169: 0.36900019 | E169: 0.257 | F169: 0 | G169: 1 | H169: 0.68245451 | I169: 0.87762856 | J169: 0 | K169: 0.62311628 | L169: 0 | M169: 0.349 | N169: 0.509 | O169: 0.63848289 | P169: 0.84 | Q169: 0.30094783 | R169: 0 | S169: 0.82634349 | T169: 0.34166486 | U169: 0 | V169: 0.1079833 | W169: 1 | X169: 1 | Y169: 0 | Z169: 0 | AA169: 1 | AB169: 0.36998878 | AC169: 0 | AD169: 0 | AE169: 0 | AF169: ='Datos Modificaciones Bus Europa'!G171 -> 0.16448571 | AG169: ='Datos Modificaciones Bus Europa'!F171 -> 0.16122857 | AH169: 1

Sheet Datos Modificaciones Bus Europa
F2: 10% más barato | G2: 10% aumento es el límite | I2: Precio del Run inicial | K2: Importaciones y Exportaciones en Francia | AD2: Modelo Objetivo | AG2: Modelo Objetivo | AH2: Generador 2
B3: Hora | C3: Generación 2 FRh2 | D3: Demanda FRh2 | E3: Demanda EUh2 | F3: M.Cost Gen EUh2 | G3: M.Cost FRh2 gen+ | I3: FR_hydrogen_bus | K3: FRh2-FRh2S | L3: FRh2S-FRh2 | M3: FRh2-LUh2 | N3: LUh2-FRh2 | O3: FRh2S-FRh2SW | P3: FRh2SW-FRh2S | Q3: BEh2-FRh2 | R3: FRh2-BEh2 | S3: BEh2-FRh2N | T3: FRh2N-BEh2 | U3: DEh2-FRh2 | V3: FRh2-DEh2 | W3: FRh2-FRh2S | X3: FRh2S-FRh2 | Y3: FRh2SW-FRh2S | Z3: Ammonia_FRN-FRh2N | AA3: Ammonia_FRSW-FRh2SW | AB3: FRh2-e-liquids | AD3: Line Flow FRh2-FRh2S | AE3: FRh2-FRh2S | AF3: FRh2S-FRh2 | AG3: Demanda 1 | AH3: Demanda 2
B4: =1 -> 1 | C4: =AH4 -> 10116.525 | D4: =AG4 -> 6779.661 | E4: =AH4 -> 10116.525 | F4: =0.99*I4 -> 144.7479 | G4: =1.01*I4 -> 147.6721 | I4: 146.21 | K4: 0 | L4: 6779.661 | M4: 1447.7401 | N4: 0 | O4: 0 | P4: 1553.6723 | Q4: 0 | R4: 1271.1864 | S4: 0 | T4: 847.5 | U4: 0 | V4: 7397.5989 | W4: 0 | X4: 6779.661 | Y4: 1553.6723 | Z4: 847.5 | AA4: 735.835 | AB4: 461.65552 | AD4: -6779.661 | AE4: =IF(AD4<0,0,AD4) -> 0 | AF4: =IF(AD4>0,0,-AD4) -> 6779.661 | AG4: 6779.661 | AH4: =M4+R4+V4 -> 10116.525
B5: =B4+1 -> 2 | C5: =AH5 -> 10116.525 | D5: =AG5 -> 6779.661 | E5: =AH5 -> 10116.525 | F5: =0.99*I5 -> 11.8998 | G5: =1.01*I5 -> 12.1402 | I5: 12.02 | K5: 0 | L5: 6779.661 | M5: 1447.7401 | N5: 0 | O5: 0 | P5: 1553.6723 | Q5: 0 | R5: 1271.1864 | S5: 0 | T5: 847.5 | U5: 0 | V5: 7397.5989 | W5: 0 | X5: 6779.661 | Y5: 1553.6723 | Z5: 847.5 | AA5: 735.835 | AB5: 461.65552 | AD5: -6779.661 | AE5: =IF(AD5<0,0,AD5) -> 0 | AF5: =IF(AD5>0,0,-AD5) -> 6779.661 | AG5: 6779.661 | AH5: =M5+R5+V5 -> 10116.525
B6: =B5+1 -> 3 | C6: =AH6 -> 10116.525 | D6: =AG6 -> 6779.661 | E6: =AH6 -> 10116.525 | F6: =0.99*I6 -> 11.8998 | G6: =1.01*I6 -> 12.1402 | I6: 12.02 | K6: 0 | L6: 6779.661 | M6: 1447.7401 | N6: 0 | O6: 0 | P6: 1553.6723 | Q6: 0 | R6: 1271.1864 | S6: 0 | T6: 847.5 | U6: 0 | V6: 7397.5989 | W6: 0 | X6: 6779.661 | Y6: 1553.6723 | Z6: 847.5 | AA6: 735.835 | AB6: 461.65552 | AD6: -6779.661 | AE6: =IF(AD6<0,0,AD6) -> 0 | AF6: =IF(AD6>0,0,-AD6) -> 6779.661 | AG6: 6779.661 | AH6: =M6+R6+V6 -> 10116.525
B7: =B6+1 -> 4 | C7: =AH7 -> 10116.525 | D7: =AG7 -> 6779.661 | E7: =AH7 -> 10116.525 | F7: =0.99*I7 -> 11.8998 | G7: =1.01*I7 -> 12.1402 | I7: 12.02 | K7: 0 | L7: 6779.661 | M7: 1447.7401 | N7: 0 | O7: 0 | P7: 1553.6723 | Q7: 0 | R7: 1271.1864 | S7: 0 | T7: 847.5 | U7: 0 | V7: 7397.5989 | W7: 0 | X7: 6779.661 | Y7: 1553.6723 | Z7: 847.5 | AA7: 735.835 | AB7: 461.65552 | AD7: -6779.661 | AE7: =IF(AD7<0,0,AD7) -> 0 | AF7: =IF(AD7>0,0,-AD7) -> 6779.661 | AG7: 6779.661 | AH7: =M7+R7+V7 -> 10116.525
B8: =B7+1 -> 5 | C8: =AH8 -> 10116.525 | D8: =AG8 -> 6779.661 | E8: =AH8 -> 10116.525 | F8: =0.99*I8 -> 9.9198 | G8: =1.01*I8 -> 10.1202 | I8: 10.02 | K8: 0 | L8: 6779.661 | M8: 1447.7401 | N8: 0 | O8: 0 | P8: 1553.6723 | Q8: 0 | R8: 1271.1864 | S8: 0 | T8: 847.5 | U8: 0 | V8: 7397.5989 | W8: 0 | X8: 6779.661 | Y8: 1553.6723 | Z8: 847.5 | AA8: 735.835 | AB8: 453.37765 | AD8: -6779.661 | AE8: =IF(AD8<0,0,AD8) -> 0 | AF8: =IF(AD8>0,0,-AD8) -> 6779.661 | AG8: 6779.661 | AH8: =M8+R8+V8 -> 10116.525
B9: =B8+1 -> 6 | C9: =AH9 -> 10116.525 | D9: =AG9 -> 6779.661 | E9: =AH9 -> 10116.525 | F9: =0.99*I9 -> 9.9198 | G9: =1.01*I9 -> 10.1202 | I9: 10.02 | K9: 0 | L9: 6779.661 | M9: 1447.7401 | N9: 0 | O9: 0 | P9: 1553.6723 | Q9: 0 | R9: 1271.1864 | S9: 0 | T9: 847.5 | U9: 0 | V9: 7397.5989 | W9: 0 | X9: 6779.661 | Y9: 1553.6723 | Z9: 847.5 | AA9: 735.835 | AB9: 436.8219 | AD9: -6779.661 | AE9: =IF(AD9<0,0,AD9) -> 0 | AF9: =IF(AD9>0,0,-AD9) -> 6779.661 | AG9: 6779.661 | AH9: =M9+R9+V9 -> 10116.525
B10: =B9+1 -> 7 | C10: =AH10 -> 10116.525 | D10: =AG10 -> 6779.661 | E10: =AH10 -> 10116.525 | F10: =0.99*I10 -> 9.9198 | G10: =1.01*I10 -> 10.1202 | I10: 10.02 | K10: 0 | L10: 6779.661 | M10: 1447.7401 | N10: 0 | O10: 0 | P10: 1553.6723 | Q10: 0 | R10: 1271.1864 | S10: 0 | T10: 847.5 | U10: 0 | V10: 7397.5989 | W10: 0 | X10: 6779.661 | Y10: 1553.6723 | Z10: 847.5 | AA10: 735.835 | AB10: 428.54402 | AD10: -6779.661 | AE10: =IF(AD10<0,0,AD10) -> 0 | AF10: =IF(AD10>0,0,-AD10) -> 6779.661 | AG10: 6779.661 | AH10: =M10+R10+V10 -> 10116.525
B11: =B10+1 -> 8 | C11: =AH11 -> 10116.525 | D11: =AG11 -> 6779.661 | E11: =AH11 -> 10116.525 | F11: =0.99*I11 -> 11.8998 | G11: =1.01*I11 -> 12.1402 | I11: 12.02 | K11: 0 | L11: 6779.661 | M11: 1447.7401 | N11: 0 | O11: 0 | P11: 1553.6723 | Q11: 0 | R11: 1271.1864 | S11: 0 | T11: 847.5 | U11: 0 | V11: 7397.5989 | W11: 0 | X11: 6779.661 | Y11: 1553.6723 | Z11: 847.5 | AA11: 735.835 | AB11: 420.26615 | AD11: -6779.661 | AE11: =IF(AD11<0,0,AD11) -> 0 | AF11: =IF(AD11>0,0,-AD11) -> 6779.661 | AG11: 6779.661 | AH11: =M11+R11+V11 -> 10116.525
B12: =B11+1 -> 9 | C12: =AH12 -> 10116.525 | D12: =AG12 -> 6779.661 | E12: =AH12 -> 10116.525 | F12: =0.99*I12 -> 11.8998 | G12: =1.01*I12 -> 12.1402 | I12: 12.02 | K12: 0 | L12: 6779.661 | M12: 1447.7401 | N12: 0 | O12: 0 | P12: 1553.6723 | Q12: 0 | R12: 1271.1864 | S12: 0 | T12: 847.5 | U12: 0 | V12: 7397.5989 | W12: 0 | X12: 6779.661 | Y12: 1553.6723 | Z12: 847.5 | AA12: 735.835 | AB12: 420.26615 | AD12: -6779.661 | AE12: =IF(AD12<0,0,AD12) -> 0 | AF12: =IF(AD12>0,0,-AD12) -> 6779.661 | AG12: 6779.661 | AH12: =M12+R12+V12 -> 10116.525
B13: =B12+1 -> 10 | C13: =AH13 -> 10116.525 | D13: =AG13 -> 6779.661 | E13: =AH13 -> 10116.525 | F13: =0.99*I13 -> 11.8998 | G13: =1.01*I13 -> 12.1402 | I13: 12.02 | K13: 0 | L13: 6779.661 | M13: 1447.7401 | N13: 0 | O13: 0 | P13: 1553.6723 | Q13: 0 | R13: 1271.1864 | S13: 0 | T13: 847.5 | U13: 0 | V13: 7397.5989 | W13: 0 | X13: 6779.661 | Y13: 1553.6723 | Z13: 847.5 | AA13: 735.835 | AB13: 420.26615 | AD13: -6779.661 | AE13: =IF(AD13<0,0,AD13) -> 0 | AF13: =IF(AD13>0,0,-AD13) -> 6779.661 | AG13: 6779.661 | AH13: =M13+R13+V13 -> 10116.525
B14: =B13+1 -> 11 | C14: =AH14 -> 10116.525 | D14: =AG14 -> 6779.661 | E14: =AH14 -> 10116.525 | F14: =0.99*I14 -> 0.16122857 | G14: =1.01*I14 -> 0.16448571 | I14: 0.16285714 | K14: 0 | L14: 6779.661 | M14: 1447.7401 | N14: 0 | O14: 0 | P14: 1553.6723 | Q14: 0 | R14: 1271.1864 | S14: 0 | T14: 847.5 | U14: 0 | V14: 7397.5989 | W14: 0 | X14: 6779.661 | Y14: 1553.6723 | Z14: 847.5 | AA14: 735.835 | AB14: 420.26615 | AD14: -6779.661 | AE14: =IF(AD14<0,0,AD14) -> 0 | AF14: =IF(AD14>0,0,-AD14) -> 6779.661 | AG14: 6779.661 | AH14: =M14+R14+V14 -> 10116.525
B15: =B14+1 -> 12 | C15: =AH15 -> 10116.525 | D15: =AG15 -> 6779.661 | E15: =AH15 -> 10116.525 | F15: =0.99*I15 -> 0.16122857 | G15: =1.01*I15 -> 0.16448571 | I15: 0.16285714 | K15: 0 | L15: 6779.661 | M15: 1447.7401 | N15: 0 | O15: 0 | P15: 1521.4124 | Q15: 0 | R15: 1271.1864 | S15: 0 | T15: 847.5 | U15: 0 | V15: 7397.5989 | W15: 0 | X15: 6779.661 | Y15: 1521.4124 | Z15: 847.5 | AA15: 735.835 | AB15: 428.54402 | AD15: -6779.661 | AE15: =IF(AD15<0,0,AD15) -> 0 | AF15: =IF(AD15>0,0,-AD15) -> 6779.661 | AG15: 6779.661 | AH15: =M15+R15+V15 -> 10116.525
B16: =B15+1 -> 13 | C16: =AH16 -> 10116.525 | D16: =AG16 -> 6779.661 | E16: =AH16 -> 10116.525 | F16: =0.99*I16 -> 0.16122857 | G16: =1.01*I16 -> 0.16448571 | I16: 0.16285714 | K16: 0 | L16: 6779.661 | M16: 1447.7401 | N16: 0 | O16: 0 | P16: 504.93229 | Q16: 0 | R16: 1271.1864 | S16: 0 | T16: 847.5 | U16: 0 | V16: 7397.5989 | W16: 0 | X16: 6779.661 | Y16: 504.93229 | Z16: 847.5 | AA16: 735.835 | AB16: 436.8219 | AD16: -6779.661 | AE16: =IF(AD16<0,0,AD16) -> 0 | AF16: =IF(AD16>0,0,-AD16) -> 6779.661 | AG16: 6779.661 | AH16: =M16+R16+V16 -> 10116.525
... B171: =B170+1 -> 168 | C171: =AH171 -> 10116.525 | D171: =AG171 -> 6779.661 | E171: =AH171 -> 10116.525 | F171: =0.99*I171 -> 0.16122857 | G171: =1.01*I171 -> 0.16448571 | I171: 0.16285714 | K171: 0 | L171: 6779.661 | M171: 1447.7401 | N171: 0 | O171: 0 | P171: 244.84131 | Q171: 0 | R171: 1271.1864 | S171: 0 | T171: 847.5 | U171: 0 | V171: 7397.5989 | W171: 0 | X171: 6779.661 | Y171: 244.84131 | Z171: 847.5 | AA171: 735.835 | AB171: 463.24924 | AD171: -6779.661 | AE171: =IF(AD171<0,0,AD171) -> 0 | AF171: =IF(AD171>0,0,-AD171) -> 6779.661 | AG171: 6779.661 | AH171: =M171+R171+V171 -> 10116.525

Sheet Obtencion de Datos
A1: Capacidades Instaladas | D1: ESPAÑA | I1: PORTUGAL | L1: FRANCIA | P1: Solar ES-PT | AF1: Wind | AV1: Biomasa | BC1: Nuclear | BF1: SRES: e-market o h2 | BT1: Exportaciones desde FR00 a EU00 | CA1: Esto será la demanda que pondré en el nodo EU00. Son las exportaciones del resto de europa | CL1: Importaciones desde EU00 a FR00 | CS1: Esto será la generación que tiene que tener el nodo EU00. Son las exportaciones del resto de europa | DD1: Demandas Electricidad | DM1: Demandas Hidrógeno | DW1: Exportaciones EUh2 | EO1: Load EUh2 | EP1: Generador EUh2 | ER1: CCGT | EY1: Perfil Turbina | FF1: Perfil Pump | FV1: FRh2SW | GC1: SRES Electrolyzer | GI1: WS071 | GO1: 1492.3021
A2: Capacidades Instaladas | D2: ES00 Gas CCGT present 1 | E2: 24559.65 | F2: 21481.309 | G2: =F2/E2 -> 0.8746586 | I2: PT00 Gas CCGT present 1 | J2: 1357 | L2: FR00 Gas CCGT new | M2: 414 | P2: Horas | Q2: ES00 Solar PV Utility | R2: Perfil | S2: ES00 Solar CSP | T2: Perfil | U2: ES00RETE Solar PV Rooftop | V2: Perfil | W2: PT00 Solar PV Utility | X2: Perfil | Y2: PT00RETE Solar PV Rooftop | Z2: Perfil | AA2: FR00 Solar PV Utility | AB2: Perfil | AC2: FR00RETE Solar PV Rooftop | AD2: Perfil | AF2: Horas | AG2: ES00 Wind Onshore | AH2: ES00 Wind Offshore Radial | AI2: ES00 Wind Offshore Hub Ready | AJ2: Perfil On | AK2: Perfil Off | AL2: Perfil Hub | AM2: PT00 Wind Offshore Radial | AN2: PT00 Wind Onshore | AO2: Perfil Off | AP2: Perfil On | AQ2: FR00 Wind Onshore | AR2: FR00 Wind Offshore Radial | AS2: Perfil On | AT2: Perfil Of | AV2: ES00 Other RES | AW2: Perfil | AX2: PT00 Other RES | AY2: Perfil | AZ2: FR00 Other RES | BA2: Perfil | BC2: FR00 Nuclear | BD2: Perfil | BF2: ES00_SRES_P2G | BG2: ES00_SRES_RES_Solar | BH2: ES00_SRES_RES_Wind_Onshore | BI2: Perfil SRES to h2 | BJ2: Perfil SRES emarket | BK2: PT00_SRES_RES_Solar | BL2: PT00_SRES_RES_Wind_Offshore | BM2: PT00_SRES_RES_Wind_Onshore | BN2: PT00_SRES_P2G | BO2: Perfil SRES to h2 | BP2: Perfil SRES emarket | BQ2: FR00-FRh2-P2G_emarket - generation | BR2: FR00-FRh2SW-P2G_emarket - generation | BT2: FR00-IE00 | BU2: FR00-IE00 | BV2: FR00-ITN1 | BW2: FR00-ITN1 | BX2: FR00-LUF1 | BY2: FR00-ITN1 | BZ2: FR00-UK00 | CA2: FR00-ITN1 | CB2: BE00-FR00 | CC2: FR00-ITN1 | CD2: CH00-FR00 | CE2: FR00-ITN1 | CF2: DE00-FR00 | CG2: FR00-ITN1 | CH2: FR00-FR00RETE | CI2: FR00-ITN1 | CJ2: Exportaciones FR00 | CL2: FR00-IE00 | CM2: FR00-IE00 | CN2: FR00-ITN1 | CO2: FR00-ITN1 | CP2: FR00-LUF1 | CQ2: FR00-ITN1 | CR2: FR00-UK00 | CS2: FR00-ITN1 | CT2: BE00-FR00 | CU2: FR00-ITN1 | CV2: CH00-FR00 | CW2: FR00-ITN1 | CX2: DE00-FR00 | CY2: FR00-ITN1 | CZ2: FR00-FR00RETE | DA2: FR00-ITN1 | DB2: Importaciones FR00 | DD2: ES00 Native Demand [MW_e] | DE2: ES00 Fixed Demand [MW_e] | DF2: ES00RETE Native Demand [MW_e] | DG2: ES00_demand | DH2: PT00 Native Demand | DI2: FR00 Native Demand [MW_e] | DJ2: Native Demand FR00RETE | DK2: FR00_demand | DM2: ESh2 H2 Heat Demand [GJ] | DN2: ESh2 Native Demand [MW_H2] | DO2: ESh2 Demand | DP2: PTh2 Native Demand | DQ2: FRh2 Native Demand | DR2: FRh2-e-liquids | DS2: FRh2_demand | DT2: FRh2S Native Demand [MW_H2] | DU2: FRh2SW Native Demand [MW_H2] | DW2: FRh2-FRh2S | DX2: FRh2S-FRh2 | DY2: FRh2-LUh2 | DZ2: LUh2-FRh2 | EA2: FRh2S-FRh2SW | EB2: FRh2SW-FRh2S | EC2: BEh2-FRh2 | ED2: FRh2-BEh2 | EE2: BEh2-FRh2N | EF2: FRh2N-BEh2 | EG2: DEh2-FRh2 | EH2: FRh2-DEh2 | EI2: FRh2-FRh2S | EJ2: FRh2S-FRh2 | EK2: FRh2SW-FRh2S | EL2: Ammonia_FRN-FRh2N | EM2: Ammonia_FRSW-FRh2SW | EN2: FRh2-e-liquids | EO2: Exportaciones EUh2 | EP2: Importaciones EU a FRh2 | ER2: Others non Renewables | ES2: Generado TYNDP CCGT ES | ET2: Perfil Gas ES | EU2: PT00 Gas CCGT present 1 | EV2: Others non-renewable [MW_e] | EW2: Perfil Gas PT | EY2: ES00 PS Closed | EZ2: ES00 PS Open | FA2: Perfil ES | FB2: Pump Storage - Open Loop (turbine) [MW_e] | FC2: Perfil PT | FF2: ES00 PS Open Pump | FG2: ES00 PS Closed Pump | FH2: Perfil ES | FI2: Pump Storage - Open Loop (pump) [MW_e] | FJ2: Perfil PT | FL2: Reservoir | FM2: Perfil ES | FN2: PT00 Reservoir | FO2: Perfil PT | FQ2: Pondage | FR2: PT00 Run of River | FS2: Perfil | FT2: Suma RoR y Pondage | FV2: FRh2SW Generation | FW2: FRh2SW-FRh2S | FX2: Load FRh2SW_storage | FY2: Generation FRh2SW Storage | FZ2: Perfil | GA2: Irún Larrao | GC2: Modelo Objetivo | GD2: Perfil ES | GE2: Modelo Objetivo | GF2: Perfil PT | GH2: 10455.164 | GI2: 1409.6684 | GK2: ES_ccgt_profile | GL2: PT_ccgt_profile | GN2: ESh2-MA | GR2: ES | GS2: PT
A3: ES Solar PV Utility | B3: 83000 | D3: ES00 Other nonRES 1 | E3: 4207.028 | I3: PT00 Other nonRES 1 | J3: 468.996 | L3: FR00 Nuclear | M3: 69619.971 | P3: 1 | Q3: 0 | R3: 0 | S3: 0 | T3: 0 | U3: 0 | V3: 0 | W3: 0 | X3: 0 | Y3: 0 | Z3: 0 | AA3: 0 | AB3: 0 | AC3: 0 | AD3: 0 | AF3: 1 | AG3: 24474.945 | AH3: 1267.3 | AI3: 275.5 | AJ3: 0.275 | AK3: 0.551 | AL3: 0.551 | AM3: 85.272 | AN3: 1385.5884 | AO3: 0.132 | AP3: 0.119 | AQ3: 15208.6 | AR3: 13568.55 | AS3: 0.341 | AT3: 0.578 | AV3: 662.456 | AW3: 0.26900019 | AX3: 863.942 | AY3: 0.5376117 | AZ3: 1121.478 | BA3: 0.57843924 | BC3: 51358.995 | BD3: 0.73770492 | BF3: 10455.164 | BG3: 0 | BH3: 0 | BI3: 0.32071055 | BJ3: 0 | BK3: 0 | BL3: 0 | BM3: 0 | BN3: 1409.668 | BO3: 0.1045903 | BP3: 0 | BQ3: 7668 | BR3: 648.91952 | BT3: -700 | BU3: 0 | BV3: 4485 | BW3: 4485 | BX3: 0 | BY3: 0 | BZ3: -5000 | CA3: 0 | CB3: -716.91477 | CC3: 0 | CD3: -4000 | CE3: 0 | CF3: 4800 | CG3: 4800 | CH3: 14492.933 | CI3: 14492.933 | CJ3: 23777.933 | CL3: -700 | CM3: 700 | CN3: 4485 | CO3: 0 | CP3: 0 | CQ3: 0 | CR3: -5000 | CS3: 5000 | CT3: -716.91477 | CU3: 716.91477 | CV3: -4000 | CW3: 4000 | CX3: 4800 | CY3: 0 | CZ3: 14492.933 | DA3: 0 | DB3: 10416.915 | DD3: 29610.763 | DE3: 2130.936 | DF3: 1169.3201 | DG3: 32911.019 | DH3: 7726.718 | DI3: 52192.411 | DJ3: 6163 | DK3: 58355.411 | DM3: 719.888 | DN3: 10493.066 | DO3: 11212.954 | DP3: 1194.7295 | DQ3: 2899.4801 | DR3: 461.65552 | DS3: 3361.1356 | DT3: 161.08223 | DU3: 161.08223 | DW3: 0 | DX3: 6779.661 | DY3: 1447.7401 | DZ3: 0 | EA3: 0 | EB3: 1553.6723 | EC3: 0 | ED3: 1271.1864 | EE3: 0 | EF3: 847.5 | EG3: 0 | EH3: 7397.5989 | EI3: 0 | EJ3: 6779.661 | EK3: 1553.6723 | EL3: 847.5 | EM3: 735.835 | EN3: 461.65552 | EO3: 10964.025 | EP3: 0 | ER3: 0 | ES3: 0 | ET3: =(ES3+ER3)/($E$2+$E$3) -> 0 | EU3: 0 | EV3: 0 | EW3: =(EU3+EV3)/($J$2+$J$3) -> 0 | EY3: 0 | EZ3: 3156.57 | FA3: =(EY3+EZ3)/($E$12+$E$14) -> 0.23203283 | FB3: 4613 | FC3: =FB3/$J$10 -> 1 | FF3: 0 | FG3: 0 | FH3: =(FF3+FG3)/($E$13+$E$15) -> 0 | FI3: 0 | FJ3: =FI3/$J$11 -> 0 | FL3: 7873 | FM3: =FL3/$E$11 -> 0.68245451 | FN3: 2591 | FO3: =FN3/$J$9 -> 0.82634349 | FQ3: 0 | FR3: 367.01 | FS3: =(FQ3+FR3)/($J$8+$J$12) -> 0.46568963 | FT3: =FQ3+FR3 -> 367.01 | FV3: =FW3+FX3-FY3-GA3 -> 1223.6723 | FW3: 1553.6723 | FX3: 0 | FY3: 330 | FZ3: =FV3/1553.6723 -> 0.78759999 | GA3: 0 | GC3: 7423.1664 | GD3: =GC3/32600 -> 0.22770449 | GE3: 1000.8643 | GF3: =GE3/13478 -> 0.07425911 | GH3: 11188.317 | GI3: 1295.2331 | GK3: 0.257 | GL3: 0.84 | GM3: =-GN3 -> 2618.1494 | GN3: -2618.1494 | GO3: =GM3-1517.77579117 -> 1100.3736 | GP3: =GO3/1492.3021 -> 0.73736651 | GR3: WS071 | GS3: WS071 | GV3: 3776.591 | GW3: 1100.3736 | GX3: =MAX(GW:GW) -> 1537.0311 | GY3: =GW3/GX3 -> 0.71590848
A4: ES Solar CSP | B4: 4805 | D4: ES00 Wind Onshore | E4: 88999.8 | F4: 78853.823 | G4: =F4/E4 -> 0.886 | I4: PT00 Wind Onshore | J4: 11643.6 | L4: FR00 Other nonRES 1 | M4: 1390 | P4: 2 | Q4: 0 | R4: 0 | S4: 0 | T4: 0 | U4: 0 | V4: 0 | W4: 0 | X4: 0 | Y4: 0 | Z4: 0 | AA4: 0 | AB4: 0 | AC4: 0 | AD4: 0 | AF4: 2 | AG4: 26165.941 | AH4: 1400.7 | AI4: 304.5 | AJ4: 0.294 | AK4: 0.609 | AL4: 0.609 | AM4: 76.228 | AN4: 1455.45 | AO4: 0.118 | AP4: 0.125 | AQ4: 16591.2 | AR4: 16127.325 | AS4: 0.372 | AT4: 0.687 | AV4: 657.53 | AW4: 0.26699991 | AX4: 857.852 | AY4: 0.53382203 | AZ4: 1121.478 | BA4: 0.57843924 | BC4: 51358.995 | BD4: 0.73770492 | BF4: 11188.317 | BG4: 0 | BH4: 0 | BI4: 0.34319991 | BJ4: 0 | BK4: 0 | BL4: 0 | BM4: 0 | BN4: 1295.233 | BO4: 0.096099792 | BP4: 0 | BQ4: 7668 | BR4: 648.91952 | BT4: -700 | BU4: 0 | BV4: 4485 | BW4: 4485 | BX4: 0 | BY4: 0 | BZ4: -5000 | CA4: 0 | CB4: 0 | CC4: 0 | CD4: -4000 | CE4: 0 | CF4: 4800 | CG4: 4800 | CH4: 10757.922 | CI4: 10757.922 | CJ4: 20042.922 | CL4: -700 | CM4: 700 | CN4: 4485 | CO4: 0 | CP4: 0 | CQ4: 0 | CR4: -5000 | CS4: 5000 | CT4: 0 | CU4: 0 | CV4: -4000 | CW4: 4000 | CX4: 4800 | CY4: 0 | CZ4: 10757.922 | DA4: 0 | DB4: 9700 | DD4: 28009.474 | DE4: 2090.089 | DF4: 888.6679 | DG4: 30988.231 | DH4: 7402.483 | DI4: 51263.411 | DJ4: 6232 | DK4: 57495.411 | DM4: 744.829 | DN4: 10493.066 | DO4: 11237.895 | DP4: 1194.7295 | DQ4: 2899.4801 | DR4: 461.65552 | DS4: 3361.1356 | DT4: 161.08223 | DU4: 161.08223 | DW4: 0 | DX4: 6779.661 | DY4: 1447.7401 | DZ4: 0 | EA4: 0 | EB4: 1553.6723 | EC4: 0 | ED4: 1271.1864 | EE4: 0 | EF4: 847.5 | EG4: 0 | EH4: 7397.5989 | EI4: 0 | EJ4: 6779.661 | EK4: 1553.6723 | EL4: 847.5 | EM4: 735.835 | EN4: 461.65552 | EO4: 10964.025 | EP4: 0 | ER4: 0 | ES4: 0 | ET4: =(ES4+ER4)/($E$2+$E$3) -> 0 | EU4: 0 | EV4: 0 | EW4: =(EU4+EV4)/($J$2+$J$3) -> 0 | EY4: 0 | EZ4: 3156.57 | FA4: =(EY4+EZ4)/($E$12+$E$14) -> 0.23203283 | FB4: 4613 | FC4: =FB4/$J$10 -> 1 | FF4: 0 | FG4: 6233.0945 | FH4: =(FF4+FG4)/($E$13+$E$15) -> 0.46792369 | FI4: 0 | FJ4: =FI4/$J$11 -> 0 | FL4: 7873 | FM4: =FL4/$E$11 -> 0.68245451 | FN4: 2591 | FO4: =FN4/$J$9 -> 0.82634349 | FQ4: 278 | FR4: 367.01 | FS4: =(FQ4+FR4)/($J$8+$J$12) -> 0.81843675 | FT4: =FQ4+FR4 -> 645.01 | FV4: =FW4+FX4-FY4-GA4 -> 1223.6723 | FW4: 1553.6723 | FX4: 0 | FY4: 330 | FZ4: =FV4/1553.6723 -> 0.78759999 | GA4: 0 | GC4: 7943.7051 | GD4: =GC4/32600 -> 0.24367193 | GE4: 919.61543 | GF4: =GE4/13478 -> 0.068230853 | GH4: 11379.209 | GI4: 1219.3706 | GK4: 0.257 | GL4: 0.84 | GM4: =-GN4 -> 2618.1494 | GN4: -2618.1494 | GO4: =GM4-1517.77579117 -> 1100.3736 | GP4: =GO4/1492.3021 -> 0.73736651 | GR4: 10455.164 | GS4: 1409.6684 | GV4: 3776.591 | GW4: 1100.3736 | GX4: =MAX(GW:GW) -> 1537.0311 | GY4: =GW4/GX4 -> 0.71590848
A5: ES Solar Rooftop | B5: 30000 | D5: ES00 Solar PV Utility | E5: 83000 | I5: PT00 Solar PV Utility | J5: 14378.2 | L5: FR00 Wind Onshore | M5: 44600 | P5: 3 | Q5: 0 | R5: 0 | S5: 0 | T5: 0 | U5: 0 | V5: 0 | W5: 0 | X5: 0 | Y5: 0 | Z5: 0 | AA5: 0 | AB5: 0 | AC5: 0 | AD5: 0 | AF5: 3 | AG5: 26610.94 | AH5: 1465.1 | AI5: 318.5 | AJ5: 0.299 | AK5: 0.637 | AL5: 0.637 | AM5: 71.06 | AN5: 1595.1732 | AO5: 0.11 | AP5: 0.137 | AQ5: 18375.2 | AR5: 17653.2 | AS5: 0.412 | AT5: 0.752 | AV5: 652.605 | AW5: 0.26500004 | AX5: 856.538 | AY5: 0.53300436 | AZ5: 1121.478 | BA5: 0.57843924 | BC5: 51358.995 | BD5: 0.73770492 | BF5: 11379.209 | BG5: 0 | BH5: 0 | BI5: 0.34905549 | BJ5: 0 | BK5: 0 | BL5: 0 | BM5: 0 | BN5: 1219.371 | BO5: 0.090471212 | BP5: 0 | BQ5: 7668 | BR5: 648.91952 | BT5: -700 | BU5: 0 | BV5: 4485 | BW5: 4485 | BX5: 0 | BY5: 0 | BZ5: -5000 | CA5: 0 | CB5: -2222.619 | CC5: 0 | CD5: -4000 | CE5: 0 | CF5: 4800 | CG5: 4800 | CH5: 10279.41 | CI5: 10279.41 | CJ5: 19564.41 | CL5: -700 | CM5: 700 | CN5: 4485 | CO5: 0 | CP5: 0 | CQ5: 0 | CR5: -5000 | CS5: 5000 | CT5: -2222.619 | CU5: 2222.619 | CV5: -4000 | CW5: 4000 | CX5: 4800 | CY5: 0 | CZ5: 10279.41 | DA5: 0 | DB5: 11922.619 | DD5: 26842.165 | DE5: 2042.995 | DF5: 1460.145 | DG5: 30345.305 | DH5: 7034.883 | DI5: 49580.411 | DJ5: 6311 | DK5: 55891.411 | DM5: 804.373 | DN5: 10493.066 | DO5: 11297.439 | DP5: 1194.7295 | DQ5: 2899.4801 | DR5: 461.65552 | DS5: 3361.1356 | DT5: 161.08223 | DU5: 161.08223 | DW5: 0 | DX5: 6779.661 | DY5: 1447.7401 | DZ5: 0 | EA5: 0 | EB5: 1553.6723 | EC5: 0 | ED5: 1271.1864 | EE5: 0 | EF5: 847.5 | EG5: 0 | EH5: 7397.5989 | EI5: 0 | EJ5: 6779.661 | EK5: 1553.6723 | EL5: 847.5 | EM5: 735.835 | EN5: 461.65552 | EO5: 10964.025 | EP5: 0 | ER5: 0 | ES5: 0 | ET5: =(ES5+ER5)/($E$2+$E$3) -> 0 | EU5: 0 | EV5: 0 | EW5: =(EU5+EV5)/($J$2+$J$3) -> 0 | EY5: 0 | EZ5: 3156.57 | FA5: =(EY5+EZ5)/($E$12+$E$14) -> 0.23203283 | FB5: 4613 | FC5: =FB5/$J$10 -> 1 | FF5: 0 | FG5: 2389.7804 | FH5: =(FF5+FG5)/($E$13+$E$15) -> 0.17940284 | FI5: 0 | FJ5: =FI5/$J$11 -> 0 | FL5: 7873 | FM5: =FL5/$E$11 -> 0.68245451 | FN5: 2591 | FO5: =FN5/$J$9 -> 0.82634349 | FQ5: 0 | FR5: 367.01 | FS5: =(FQ5+FR5)/($J$8+$J$12) -> 0.46568963 | FT5: =FQ5+FR5 -> 367.01 | FV5: =FW5+FX5-FY5-GA5 -> 1223.6723 | FW5: 1553.6723 | FX5: 0 | FY5: 330 | FZ5: =FV5/1553.6723 -> 0.78759999 | GA5: 0 | GC5: 8079.2384 | GD5: =GC5/32600 -> 0.2478294 | GE5: 865.75341 | GF5: =GE5/13478 -> 0.064234561 | GH5: 11664.809 | GI5: 1148.3197 | GK5: 0.257 | GL5: 0.84 | GM5: =-GN5 -> 2618.1494 | GN5: -2618.1494 | GO5: =GM5-1517.77579117 -> 1100.3736 | GP5: =GO5/1492.3021 -> 0.73736651 | GR5: 11188.317 | GS5: 1295.2331 | GV5: 3776.591 | GW5: 1100.3736 | GX5: =MAX(GW:GW) -> 1537.0311 | GY5: =GW5/GX5 -> 0.71590848
A6: PT Solar PV Utility | B6: 14378.2 | D6: ES00 Wind Offshore Radial | E6: 2300 | I6: PT00 Wind Offshore Radial | J6: 646 | L6: FR00 Solar PV Utility | M6: 51420 | P6: 4 | Q6: 0 | R6: 0 | S6: 0 | T6: 0 | U6: 0 | V6: 0 | W6: 0 | X6: 0 | Y6: 0 | Z6: 0 | AA6: 0 | AB6: 0 | AC6: 0 | AD6: 0 | AF6: 4 | AG6: 27322.939 | AH6: 1460.5 | AI6: 317.5 | AJ6: 0.307 | AK6: 0.635 | AL6: 0.635 | AM6: 67.83 | AN6: 1781.4708 | AO6: 0.105 | AP6: 0.153 | AQ6: 19534.8 | AR6: 18404.4 | AS6: 0.438 | AT6: 0.784 | AV6: 677.231 | AW6: 0.2749998 | AX6: 866.279 | AY6: 0.53906596 | AZ6: 1121.478 | BA6: 0.57843924 | BC6: 51358.995 | BD6: 0.73770492 | BF6: 11664.809 | BG6: 0 | BH6: 0 | BI6: 0.35781623 | BJ6: 0 | BK6: 0 | BL6: 0 | BM6: 0 | BN6: 1148.32 | BO6: 0.085199585 | BP6: 0 | BQ6: 7668 | BR6: 648.91952 | BT6: -700 | BU6: 0 | BV6: 4485 | BW6: 4485 | BX6: 0 | BY6: 0 | BZ6: -5000 | CA6: 0 | CB6: -1446.1603 | CC6: 0 | CD6: -4000 | CE6: 0 | CF6: 4800 | CG6: 4800 | CH6: 13335.643 | CI6: 13335.643 | CJ6: 22620.643 | CL6: -700 | CM6: 700 | CN6: 4485 | CO6: 0 | CP6: 0 | CQ6: 0 | CR6: -5000 | CS6: 5000 | CT6: -1446.1603 | CU6: 1446.1603 | CV6: -4000 | CW6: 4000 | CX6: 4800 | CY6: 0 | CZ6: 13335.643 | DA6: 0 | DB6: 11146.16 | DD6: 26274.437 | DE6: 2003.629 | DF6: 2313.9328 | DG6: 30591.999 | DH6: 6846.224 | DI6: 47905.411 | DJ6: 6196 | DK6: 54101.411 | DM6: 892.909 | DN6: 10493.066 | DO6: 11385.975 | DP6: 1194.7295 | DQ6: 2899.4801 | DR6: 461.65552 | DS6: 3361.1356 | DT6: 161.08223 | DU6: 161.08223 | DW6: 0 | DX6: 6779.661 | DY6: 1447.7401 | DZ6: 0 | EA6: 0 | EB6: 1553.6723 | EC6: 0 | ED6: 1271.1864 | EE6: 0 | EF6: 847.5 | EG6: 0 | EH6: 7397.5989 | EI6: 0 | EJ6: 6779.661 | EK6: 1553.6723 | EL6: 847.5 | EM6: 735.835 | EN6: 461.65552 | EO6: 10964.025 | EP6: 0 | ER6: 0 | ES6: 0 | ET6: =(ES6+ER6)/($E$2+$E$3) -> 0 | EU6: 0 | EV6: 0 | EW6: =(EU6+EV6)/($J$2+$J$3) -> 0 | EY6: 0 | EZ6: 3156.57 | FA6: =(EY6+EZ6)/($E$12+$E$14) -> 0.23203283 | FB6: 4613 | FC6: =FB6/$J$10 -> 1 | FF6: 0 | FG6: 1486.2996 | FH6: =(FF6+FG6)/($E$13+$E$15) -> 0.11157777 | FI6: 0 | FJ6: =FI6/$J$11 -> 0 | FL6: 7873 | FM6: =FL6/$E$11 -> 0.68245451 | FN6: 2591 | FO6: =FN6/$J$9 -> 0.82634349 | FQ6: 278 | FR6: 367.01 | FS6: =(FQ6+FR6)/($J$8+$J$12) -> 0.81843675 | FT6: =FQ6+FR6 -> 645.01 | FV6: =FW6+FX6-FY6-GA6 -> 1223.6723 | FW6: 1553.6723 | FX6: 0 | FY6: 330 | FZ6: =FV6/1553.6723 -> 0.78759999 | GA6: 0 | GC6: 8282.0144 | GD6: =GC6/32600 -> 0.25404952 | GE6: 815.3072 | GF6: =GE6/13478 -> 0.060491705 | GH6: 12228.817 | GI6: 1097.6028 | GK6: 0.257 | GL6: 0.84 | GM6: =-GN6 -> 2618.1494 | GN6: -2618.1494 | GO6: =GM6-1517.77579117 -> 1100.3736 | GP6: =GO6/1492.3021 -> 0.73736651 | GR6: 11379.209 | GS6: 1219.3706 | GV6: 3776.591 | GW6: 1100.3736 | GX6: =MAX(GW:GW) -> 1537.0311 | GY6: =GW6/GX6 -> 0.71590848
A7: PT Solar Rooftop | B7: 9659.9 | D7: ES00 Wind Offshore Hub Ready | E7: 500 | I7: PT00 Other RES | J7: 1607 | L7: FR00 Wind Offshore Radial | M7: 23475 | P7: 5 | Q7: 0 | R7: 0 | S7: 0 | T7: 0 | U7: 0 | V7: 0 | W7: 0 | X7: 0 | Y7: 0 | Z7: 0 | AA7: 0 | AB7: 0 | AC7: 0 | AD7: 0 | AF7: 5 | AG7: 28657.936 | AH7: 1428.3 | AI7: 310.5 | AJ7: 0.322 | AK7: 0.621 | AL7: 0.621 | AM7: 65.246 | AN7: 1944.4812 | AO7: 0.101 | AP7: 0.167 | AQ7: 20560.6 | AR7: 19132.125 | AS7: 0.461 | AT7: 0.815 | AV7: 687.082 | AW7: 0.27899994 | AX7: 871.284 | AY7: 0.54218046 | AZ7: 1121.478 | BA7: 0.57843924 | BC7: 51358.995 | BD7: 0.73770492 | BF7: 12228.817 | BG7: 0 | BH7: 0 | BI7: 0.37511709 | BJ7: 0 | BK7: 0 | BL7: 0 | BM7: 0 | BN7: 1097.603 | BO7: 0.081436637 | BP7: 0 | BQ7: 7668 | BR7: 649.3794 | BT7: -700 | BU7: 0 | BV7: 4485 | BW7: 4485 | BX7: 0 | BY7: 0 | BZ7: -5000 | CA7: 0 | CB7: -2137.9981 | CC7: 0 | CD7: -4000 | CE7: 0 | CF7: 4800 | CG7: 4800 | CH7: 12475.322 | CI7: 12475.322 | CJ7: 21760.322 | CL7: -700 | CM7: 700 | CN7: 4485 | CO7: 0 | CP7: 0 | CQ7: 0 | CR7: -5000 | CS7: 5000 | CT7: -2137.9981 | CU7: 2137.9981 | CV7: -4000 | CW7: 4000 | CX7: 4800 | CY7: 0 | CZ7: 12475.322 | DA7: 0 | DB7: 11837.998 | DD7: 26537.633 | DE7: 1976.586 | DF7: 2602.5462 | DG7: 31116.765 | DH7: 6811.541 | DI7: 47372.411 | DJ7: 6255 | DK7: 53627.411 | DM7: 1053.763 | DN7: 10508.776 | DO7: 11562.539 | DP7: 1194.7295 | DQ7: 2907.758 | DR7: 453.37765 | DS7: 3361.1356 | DT7: 161.54211 | DU7: 161.54211 | DW7: 0 | DX7: 6779.661 | DY7: 1447.7401 | DZ7: 0 | EA7: 0 | EB7: 1553.6723 | EC7: 0 | ED7: 1271.1864 | EE7: 0 | EF7: 847.5 | EG7: 0 | EH7: 7397.5989 | EI7: 0 | EJ7: 6779.661 | EK7: 1553.6723 | EL7: 847.5 | EM7: 735.835 | EN7: 453.37765 | EO7: 10964.025 | EP7: 0 | ER7: 0 | ES7: 0 | ET7: =(ES7+ER7)/($E$2+$E$3) -> 0 | EU7: 0 | EV7: 0 | EW7: =(EU7+EV7)/($J$2+$J$3) -> 0 | EY7: 0 | EZ7: 3156.57 | FA7: =(EY7+EZ7)/($E$12+$E$14) -> 0.23203283 | FB7: 4613 | FC7: =FB7/$J$10 -> 1 | FF7: 0 | FG7: 7040.3117 | FH7: =(FF7+FG7)/($E$13+$E$15) -> 0.52852217 | FI7: 0 | FJ7: =FI7/$J$11 -> 0 | FL7: 7873 | FM7: =FL7/$E$11 -> 0.68245451 | FN7: 2591 | FO7: =FN7/$J$9 -> 0.82634349 | FQ7: 0 | FR7: 367.01 | FS7: =(FQ7+FR7)/($J$8+$J$12) -> 0.46568963 | FT7: =FQ7+FR7 -> 367.01 | FV7: =FW7+FX7-FY7-GA7 -> 1223.6723 | FW7: 1553.6723 | FX7: 0 | FY7: 330 | FZ7: =FV7/1553.6723 -> 0.78759999 | GA7: 0 | GC7: 8682.4601 | GD7: =GC7/32600 -> 0.26633313 | GE7: 779.29813 | GF7: =GE7/13478 -> 0.057820013 | GH7: 12302.136 | GI7: 1069.2209 | GK7: 0.257 | GL7: 0.84 | GM7: =-GN7 -> 2618.1494 | GN7: -2618.1494 | GO7: =GM7-1517.77579117 -> 1100.3736 | GP7: =GO7/1492.3021 -> 0.73736651 | GR7: 11664.809 | GS7: 1148.3197 | GV7: 3776.591 | GW7: 1100.3736 | GX7: =MAX(GW:GW) -> 1537.0311 | GY7: =GW7/GX7 -> 0.71590848
A8: PT00 Wind Onshore | B8: 11643.6 | D8: ES00 Solar CSP | E8: 4805 | I8: PT00 Run of River | J8: 508.3 | L8: FR00 Other RES | M8: 1938.8 | P8: 6 | Q8: 0 | R8: 0 | S8: 0 | T8: 0 | U8: 0 | V8: 0 | W8: 0 | X8: 0 | Y8: 0 | Z8: 0 | AA8: 0 | AB8: 0 | AC8: 0 | AD8: 0 | AF8: 6 | AG8: 28835.935 | AH8: 1393.8 | AI8: 303 | AJ8: 0.324 | AK8: 0.606 | AL8: 0.606 | AM8: 62.662 | AN8: 2072.5608 | AO8: 0.097 | AP8: 0.178 | AQ8: 21363.4 | AR8: 19578.15 | AS8: 0.479 | AT8: 0.834 | AV8: 716.634 | AW8: 0.29099998 | AX8: 890.922 | AY8: 0.55440075 | AZ8: 1121.478 | BA8: 0.57843924 | BC8: 51358.995 | BD8: 0.73770492 | BF8: 12302.136 | BG8: 0 | BH8: 0 | BI8: 0.37736613 | BJ8: 0 | BK8: 0 | BL8: 0 | BM8: 0 | BN8: 1069.221 | BO8: 0.079330835 | BP8: 0 | BQ8: 7668 | BR8: 650.29917 | BT8: -700 | BU8: 0 | BV8: 4485 | BW8: 4485 | BX8: 0 | BY8: 0 | BZ8: -5000 | CA8: 0 | CB8: 0 | CC8: 0 | CD8: -4000 | CE8: 0 | CF8: 4800 | CG8: 4800 | CH8: 16766.796 | CI8: 16766.796 | CJ8: 26051.796 | CL8: -700 | CM8: 700 | CN8: 4485 | CO8: 0 | CP8: 0 | CQ8: 0 | CR8: -5000 | CS8: 5000 | CT8: 0 | CU8: 0 | CV8: -4000 | CW8: 4000 | CX8: 4800 | CY8: 0 | CZ8: 16766.796 | DA8: 0 | DB8: 9700 | DD8: 27552.059 | DE8: 1965.631 | DF8: 2801.3606 | DG8: 32319.051 | DH8: 6946.607 | DI8: 47878.411 | DJ8: 6340 | DK8: 54218.411 | DM8: 1230.726 | DN8: 10540.196 | DO8: 11770.922 | DP8: 1292.686 | DQ8: 2924.3137 | DR8: 436.8219 | DS8: 3361.1356 | DT8: 162.46187 | DU8: 162.46187 | DW8: 0 | DX8: 6779.661 | DY8: 1447.7401 | DZ8: 0 | EA8: 0 | EB8: 1553.6723 | EC8: 0 | ED8: 1271.1864 | EE8: 0 | EF8: 847.5 | EG8: 0 | EH8: 7397.5989 | EI8: 0 | EJ8: 6779.661 | EK8: 1553.6723 | EL8: 847.5 | EM8: 735.835 | EN8: 436.8219 | EO8: 10964.025 | EP8: 0 | ER8: 0 | ES8: 0 | ET8: =(ES8+ER8)/($E$2+$E$3) -> 0 | EU8: 0 | EV8: 0 | EW8: =(EU8+EV8)/($J$2+$J$3) -> 0 | EY8: 0 | EZ8: 3156.57 | FA8: =(EY8+EZ8)/($E$12+$E$14) -> 0.23203283 | FB8: 4613 | FC8: =FB8/$J$10 -> 1 | FF8: 0 | FG8: 10423.35 | FH8: =(FF8+FG8)/($E$13+$E$15) -> 0.78248972 | FI8: 0 | FJ8: =FI8/$J$11 -> 0 | FL8: 7873 | FM8: =FL8/$E$11 -> 0.68245451 | FN8: 2591 | FO8: =FN8/$J$9 -> 0.82634349 | FQ8: 278 | FR8: 367.01 | FS8: =(FQ8+FR8)/($J$8+$J$12) -> 0.81843675 | FT8: =FQ8+FR8 -> 645.01 | FV8: =FW8+FX8-FY8-GA8 -> 1223.6723 | FW8: 1553.6723 | FX8: 0 | FY8: 330 | FZ8: =FV8/1553.6723 -> 0.78759999 | GA8: 0 | GC8: 8734.5166 | GD8: =GC8/32600 -> 0.26792996 | GE8: 759.14691 | GF8: =GE8/13478 -> 0.056324893 | GH8: 11503.818 | GI8: 1034.4002 | GK8: 0.257 | GL8: 0.84 | GM8: =-GN8 -> 2618.1494 | GN8: -2618.1494 | GO8: =GM8-1517.77579117 -> 1100.3736 | GP8: =GO8/1492.3021 -> 0.73736651 | GR8: 12228.817 | GS8: 1097.6028 | GV8: 3776.591 | GW8: 1100.3736 | GX8: =MAX(GW:GW) -> 1537.0311 | GY8: =GW8/GX8 -> 0.71590848
A9: PT00 Wind Offshore Radial | B9: 0 | D9: ES00 Other RES | E9: 2462.66 | I9: PT00 Reservoir | J9: 3135.5 | L9: FR00 Run of River | M9: 11600 | P9: 7 | Q9: 0 | R9: 0 | S9: 0 | T9: 0 | U9: 0 | V9: 0 | W9: 0 | X9: 0 | Y9: 0 | Z9: 0 | AA9: 0 | AB9: 0 | AC9: 0 | AD9: 0 | AF9: 7 | AG9: 26966.939 | AH9: 1324.8 | AI9: 288 | AJ9: 0.303 | AK9: 0.576 | AL9: 0.576 | AM9: 59.432 | AN9: 2130.7788 | AO9: 0.092 | AP9: 0.183 | AQ9: 21809.4 | AR9: 19742.475 | AS9: 0.489 | AT9: 0.841 | AV9: 807.752 | AW9: 0.32799981 | AX9: 907.654 | AY9: 0.56481269 | AZ9: 1121.478 | BA9: 0.57843924 | BC9: 51358.995 | BD9: 0.73770492 | BF9: 11503.818 | BG9: 0 | BH9: 0 | BI9: 0.35287785 | BJ9: 0 | BK9: 0 | BL9: 0 | BM9: 0 | BN9: 1034.4 | BO9: 0.076747292 | BP9: 0 | BQ9: 7668 | BR9: 650.75905 | BT9: -700 | BU9: 0 | BV9: 4485 | BW9: 4485 | BX9: 0 | BY9: 0 | BZ9: -5000 | CA9: 0 | CB9: -1692.9681 | CC9: 0 | CD9: -4000 | CE9: 0 | CF9: 4800 | CG9: 4800 | CH9: 11390.799 | CI9: 11390.799 | CJ9: 20675.799 | CL9: -700 | CM9: 700 | CN9: 4485 | CO9: 0 | CP9: 0 | CQ9: 0 | CR9: -5000 | CS9: 5000 | CT9: -1692.9681 | CU9: 1692.9681 | CV9: -4000 | CW9: 4000 | CX9: 4800 | CY9: 0 | CZ9: 11390.799 | DA9: 0 | DB9: 11392.968 | DD9: 29332.198 | DE9: 1971.125 | DF9: 3547.0086 | DG9: 34850.332 | DH9: 7154.418 | DI9: 48168.411 | DJ9: 6425 | DK9: 54593.411 | DM9: 1295.18 | DN9: 10555.906 | DO9: 11851.086 | DP9: 1390.6425 | DQ9: 2932.5916 | DR9: 428.54402 | DS9: 3361.1356 | DT9: 162.92176 | DU9: 162.92176 | DW9: 0 | DX9: 6779.661 | DY9: 1447.7401 | DZ9: 0 | EA9: 0 | EB9: 1553.6723 | EC9: 0 | ED9: 1271.1864 | EE9: 0 | EF9: 847.5 | EG9: 0 | EH9: 7397.5989 | EI9: 0 | EJ9: 6779.661 | EK9: 1553.6723 | EL9: 847.5 | EM9: 735.835 | EN9: 428.54402 | EO9: 10964.025 | EP9: 0 | ER9: 0 | ES9: 0 | ET9: =(ES9+ER9)/($E$2+$E$3) -> 0 | EU9: 0 | EV9: 0 | EW9: =(EU9+EV9)/($J$2+$J$3) -> 0 | EY9: 0 | EZ9: 3156.57 | FA9: =(EY9+EZ9)/($E$12+$E$14) -> 0.23203283 | FB9: 4613 | FC9: =FB9/$J$10 -> 1 | FF9: 0 | FG9: 8697.2256 | FH9: =(FF9+FG9)/($E$13+$E$15) -> 0.6529081 | FI9: 0 | FJ9: =FI9/$J$11 -> 0 | FL9: 7873 | FM9: =FL9/$E$11 -> 0.68245451 | FN9: 2591 | FO9: =FN9/$J$9 -> 0.82634349 | FQ9: 0 | FR9: 367.01 | FS9: =(FQ9+FR9)/($J$8+$J$12) -> 0.46568963 | FT9: =FQ9+FR9 -> 367.01 | FV9: =FW9+FX9-FY9-GA9 -> 1223.6723 | FW9: 1553.6723 | FX9: 0 | FY9: 330 | FZ9: =FV9/1553.6723 -> 0.78759999 | GA9: 0 | GC9: 8167.7108 | GD9: =GC9/32600 -> 0.25054328 | GE9: 734.424 | GF9: =GE9/13478 -> 0.054490577 | GH9: 9322.5865 | GI9: 1038.8148 | GK9: 0.257 | GL9: 0.84 | GM9: =-GN9 -> 2618.1494 | GN9: -2618.1494 | GO9: =GM9-1517.77579117 -> 1100.3736 | GP9: =GO9/1492.3021 -> 0.73736651 | GR9: 12302.136 | GS9: 1069.2209 | GV9: 3776.591 | GW9: 1100.3736 | GX9: =MAX(GW:GW) -> 1537.0311 | GY9: =GW9/GX9 -> 0.71590848
A10: ES Biomasa | B10: 2462.66 | D10: ES00 Run of River | E10: 3117.92 | I10: PT00 PS Open | J10: 4613 | L10: FR00 Reservoir | M10: 9849.04 | P10: 8 | Q10: 0 | R10: 0 | S10: 0 | T10: 0 | U10: 0 | V10: 0 | W10: 0 | X10: 0 | Y10: 0 | Z10: 0 | AA10: 0 | AB10: 0 | AC10: 0 | AD10: 0 | AF10: 8 | AG10: 21804.951 | AH10: 1258.1 | AI10: 273.5 | AJ10: 0.245 | AK10: 0.547 | AL10: 0.547 | AM10: 58.786 | AN10: 2130.7788 | AO10: 0.091 | AP10: 0.183 | AQ10: 22121.6 | AR10: 19930.275 | AS10: 0.496 | AT10: 0.849 | AV10: 881.632 | AW10: 0.35799989 | AX10: 914.144 | AY10: 0.56885128 | AZ10: 1121.478 | BA10: 0.57843924 | BC10: 51358.995 | BD10: 0.73770492 | BF10: 9322.586 | BG10: 0 | BH10: 0 | BI10: 0.2859689 | BJ10: 0 | BK10: 0 | BL10: 0 | BM10: 0 | BN10: 1038.815 | BO10: 0.077074863 | BP10: 0 | BQ10: 7668 | BR10: 651.21893 | BT10: -700 | BU10: 0 | BV10: 4485 | BW10: 4485 | BX10: 0 | BY10: 0 | BZ10: -5000 | CA10: 0 | CB10: -1588.0746 | CC10: 0 | CD10: -4000 | CE10: 0 | CF10: 4800 | CG10: 4800 | CH10: 11792.669 | CI10: 11792.669 | CJ10: 21077.669 | CL10: -700 | CM10: 700 | CN10: 4485 | CO10: 0 | CP10: 0 | CQ10: 0 | CR10: -5000 | CS10: 5000 | CT10: -1588.0746 | CU10: 1588.0746 | CV10: -4000 | CW10: 4000 | CX10: 4800 | CY10: 0 | CZ10: 11792.669 | DA10: 0 | DB10: 11288.075 | DD10: 31087.021 | DE10: 1985.193 | DF10: 3967.9018 | DG10: 37040.116 | DH10: 7300.096 | DI10: 48105.411 | DJ10: 6568 | DK10: 54673.411 | DM10: 1287.586 | DN10: 10571.616 | DO10: 11859.202 | DP10: 1483.4434 | DQ10: 2940.8695 | DR10: 420.26615 | DS10: 3361.1356 | DT10: 163.38164 | DU10: 163.38164 | DW10: 0 | DX10: 6779.661 | DY10: 1447.7401 | DZ10: 0 | EA10: 0 | EB10: 1553.6723 | EC10: 0 | ED10: 1271.1864 | EE10: 0 | EF10: 847.5 | EG10: 0 | EH10: 7397.5989 | EI10: 0 | EJ10: 6779.661 | EK10: 1553.6723 | EL10: 847.5 | EM10: 735.835 | EN10: 420.26615 | EO10: 10964.025 | EP10: 0 | ER10: 0 | ES10: 0 | ET10: =(ES10+ER10)/($E$2+$E$3) -> 0 | EU10: 0 | EV10: 0 | EW10: =(EU10+EV10)/($J$2+$J$3) -> 0 | EY10: 0 | EZ10: 3156.57 | FA10: =(EY10+EZ10)/($E$12+$E$14) -> 0.23203283 | FB10: 4613 | FC10: =FB10/$J$10 -> 1 | FF10: 0 | FG10: 0 | FH10: =(FF10+FG10)/($E$13+$E$15) -> 0 | FI10: 0 | FJ10: =FI10/$J$11 -> 0 | FL10: 7873 | FM10: =FL10/$E$11 -> 0.68245451 | FN10: 2591 | FO10: =FN10/$J$9 -> 0.82634349 | FQ10: 0 | FR10: 367.01 | FS10: =(FQ10+FR10)/($J$8+$J$12) -> 0.46568963 | FT10: =FQ10+FR10 -> 367.01 | FV10: =FW10+FX10-FY10-GA10 -> 1223.6723 | FW10: 1553.6723 | FX10: 0 | FY10: 330 | FZ10: =FV10/1553.6723 -> 0.78759999 | GA10: 0 | GC10: 6619.0361 | GD10: =GC10/32600 -> 0.20303792 | GE10: 737.55865 | GF10: =GE10/13478 -> 0.054723153 | GH10: 7455.5241 | GI10: 1038.2046 | GK10: 0.257 | GL10: 0.84 | GM10: =-GN10 -> 2618.1494 | GN10: -2618.1494 | GO10: =GM10-1517.77579117 -> 1100.3736 | GP10: =GO10/1492.3021 -> 0.73736651 | GR10: 11503.818 | GS10: 1034.4002 | GV10: 3776.591 | GW10: 1100.3736 | GX10: =MAX(GW:GW) -> 1537.0311 | GY10: =GW10/GX10 -> 0.71590848
