Workbook

Sheet Totales
A1: Fecha | B1: DEMANDA REAL 2040
A2: 45658 | B2: ='2025-01-01'!I5 -> 35845.955
A3: 45658.042 | B3: ='2025-01-01'!I6 -> 34636.422
A4: 45658.083 | B4: ='2025-01-01'!I7 -> 32735.361
A5: 45658.125 | B5: ='2025-01-01'!I8 -> 30881.525
A6: 45658.167 | B6: ='2025-01-01'!I9 -> 29612.687
A7: 45658.208 | B7: ='2025-01-01'!I10 -> 29172.78
A8: 45658.25 | B8: ='2025-01-01'!I11 -> 29438.921
A9: 45658.292 | B9: ='2025-01-01'!I12 -> 30112.266
A10: 45658.333 | B10: ='2025-01-01'!I13 -> 30423.069
A11: 45658.375 | B11: ='2025-01-01'!I14 -> 31133.755
A12: 45658.417 | B12: ='2025-01-01'!I15 -> 32861.781
A13: 45658.458 | B13: ='2025-01-01'!I16 -> 34365.766
... A25: 45658.958 | B25: ='2025-01-01'!I28 -> 38577.532
A26: 45659 | B26: ='2025-01-02'!I5 -> 34850.457
A27: 45659.042 | B27: ='2025-01-02'!I6 -> 32122.175
A28: 45659.083 | B28: ='2025-01-02'!I7 -> 30394.027
A29: 45659.125 | B29: ='2025-01-02'!I8 -> 29481.142
A30: 45659.167 | B30: ='2025-01-02'!I9 -> 29355.454
A31: 45659.208 | B31: ='2025-01-02'!I10 -> 30433.93
A32: 45659.25 | B32: ='2025-01-02'!I11 -> 34674.86
A33: 45659.292 | B33: ='2025-01-02'!I12 -> 40256.259
A34: 45659.333 | B34: ='2025-01-02'!I13 -> 45075.232
A35: 45659.375 | B35: ='2025-01-02'!I14 -> 47918.83
A36: 45659.417 | B36: ='2025-01-02'!I15 -> 48266.973
A37: 45659.458 | B37: ='2025-01-02'!I16 -> 47331.147
... A49: 45659.958 | B49: ='2025-01-02'!I28 -> 43928.909
A50: 45660 | B50: ='2025-01-03'!I5 -> 39786.088
A51: 45660.042 | B51: ='2025-01-03'!I6 -> 36372.624
A52: 45660.083 | B52: ='2025-01-03'!I7 -> 33980.038
A53: 45660.125 | B53: ='2025-01-03'!I8 -> 32778.315
A54: 45660.167 | B54: ='2025-01-03'!I9 -> 32358.786
A55: 45660.208 | B55: ='2025-01-03'!I10 -> 33021.027
A56: 45660.25 | B56: ='2025-01-03'!I11 -> 36760.792
A57: 45660.292 | B57: ='2025-01-03'!I12 -> 41812.227
A58: 45660.333 | B58: ='2025-01-03'!I13 -> 46297.334
A59: 45660.375 | B59: ='2025-01-03'!I14 -> 48833.911
A60: 45660.417 | B60: ='2025-01-03'!I15 -> 49321.41
A61: 45660.458 | B61: ='2025-01-03'!I16 -> 48719.328
... A73: 45660.958 | B73: ='2025-01-03'!I28 -> 43665.819
...

Sheet 2025-01-01
A1: Seguimiento de la demanda de energía eléctrica (MW)
A2: Demanda anual 2024 (MWh) | B2: 241811000
A3: Demanda anual 2040 (MWh) | B3: =354.09*10^6 -> 354090000
A4: Hora | B4: Real | C4: Prevista | D4: Programada | E4: Real 2040 MW | F4: Real 2040 cada h | H4: Fecha | I4: DEMANDA REAL 2040
A5: 45658 | B5: 24620 | C5: 25043 | D5: 24805 | E5: =(B5/$B$2)*$B$3 -> 36051.692 | F5: =SUM(E5:E16)/12 -> 35845.955 | H5: 45658 | I5: =F5 -> 35845.955
A6: 45658.003 | B6: 24701 | C6: 24941 | D6: 24805 | E6: =(B6/$B$2)*$B$3 -> 36170.303 | H6: 45658.042 | I6: =F17 -> 34636.422
A7: 45658.007 | B7: 24701 | C7: 24857 | D7: 24805 | E7: =(B7/$B$2)*$B$3 -> 36170.303 | H7: 45658.083 | I7: =F29 -> 32735.361
A8: 45658.01 | B8: 24683 | C8: 24792 | D8: 24515 | E8: =(B8/$B$2)*$B$3 -> 36143.945 | H8: 45658.125 | I8: =F41 -> 30881.525
A9: 45658.014 | B9: 24546 | C9: 24737 | D9: 24515 | E9: =(B9/$B$2)*$B$3 -> 35943.332 | H9: 45658.167 | I9: =F53 -> 29612.687
A10: 45658.017 | B10: 24454 | C10: 24682 | D10: 24515 | E10: =(B10/$B$2)*$B$3 -> 35808.614 | H10: 45658.208 | I10: =F65 -> 29172.78
A11: 45658.021 | B11: 24458 | C11: 24627 | D11: 24351 | E11: =(B11/$B$2)*$B$3 -> 35814.472 | H11: 45658.25 | I11: =F77 -> 29438.921
A12: 45658.024 | B12: 24433 | C12: 24569 | D12: 24351 | E12: =(B12/$B$2)*$B$3 -> 35777.864 | H12: 45658.292 | I12: =F89 -> 30112.266
A13: 45658.028 | B13: 24382 | C13: 24501 | D13: 24351 | E13: =(B13/$B$2)*$B$3 -> 35703.183 | H13: 45658.333 | I13: =F101 -> 30423.069
A14: 45658.031 | B14: 24314 | C14: 24425 | D14: 24290 | E14: =(B14/$B$2)*$B$3 -> 35603.609 | H14: 45658.375 | I14: =F113 -> 31133.755
A15: 45658.035 | B15: 24244 | C15: 24363 | D15: 24290 | E15: =(B15/$B$2)*$B$3 -> 35501.106 | H15: 45658.417 | I15: =F125 -> 32861.781
A16: 45658.038 | B16: 24218 | C16: 24337 | D16: 24290 | E16: =(B16/$B$2)*$B$3 -> 35463.034 | H16: 45658.458 | I16: =F137 -> 34365.766
A17: 45658.042 | B17: 24138 | C17: 24288 | D17: 24040 | E17: =(B17/$B$2)*$B$3 -> 35345.888 | F17: =SUM(E17:E28)/12 -> 34636.422 | H17: 45658.5 | I17: =F149 -> 35283.41
A18: 45658.045 | B18: 24057 | C18: 24288 | D18: 24040 | E18: =(B18/$B$2)*$B$3 -> 35227.277 | H18: 45658.542 | I18: =F161 -> 36173.842
A19: 45658.049 | B19: 23979 | C19: 24233 | D19: 24040 | E19: =(B19/$B$2)*$B$3 -> 35113.06 | H19: 45658.583 | I19: =F173 -> 36673.787
A20: 45658.052 | B20: 23924 | C20: 24123 | D20: 23762 | E20: =(B20/$B$2)*$B$3 -> 35032.522 | H20: 45658.625 | I20: =F185 -> 35404.339
A21: 45658.056 | B21: 23840 | C21: 23988 | D21: 23762 | E21: =(B21/$B$2)*$B$3 -> 34909.519 | H21: 45658.667 | I21: =F197 -> 35593.359
A22: 45658.059 | B22: 23727 | C22: 23859 | D22: 23762 | E22: =(B22/$B$2)*$B$3 -> 34744.05 | H22: 45658.708 | I22: =F209 -> 37184.592
A23: 45658.062 | B23: 23606 | C23: 23736 | D23: 23510 | E23: =(B23/$B$2)*$B$3 -> 34566.866 | H23: 45658.75 | I23: =F221 -> 40983.907
A24: 45658.066 | B24: 23566 | C24: 23623 | D24: 23510 | E24: =(B24/$B$2)*$B$3 -> 34508.293 | H24: 45658.792 | I24: =F233 -> 43088.02
A25: 45658.069 | B25: 23431 | C25: 23524 | D25: 23510 | E25: =(B25/$B$2)*$B$3 -> 34310.609 | H25: 45658.833 | I25: =F245 -> 44775.411
A26: 45658.073 | B26: 23292 | C26: 23441 | D26: 23161 | E26: =(B26/$B$2)*$B$3 -> 34107.068 | H26: 45658.875 | I26: =F257 -> 44993.962
A27: 45658.076 | B27: 23180 | C27: 23327 | D27: 23161 | E27: =(B27/$B$2)*$B$3 -> 33943.064 | H27: 45658.917 | I27: =F269 -> 42622.853
A28: 45658.08 | B28: 23102 | C28: 23139 | D28: 23161 | E28: =(B28/$B$2)*$B$3 -> 33828.846 | H28: 45658.958 | I28: =F281 -> 38577.532
A29: 45658.083 | B29: 22975 | C29: 22834 | D29: 22802 | E29: =(B29/$B$2)*$B$3 -> 33642.877 | F29: =SUM(E29:E40)/12 -> 32735.361
A30: 45658.087 | B30: 22864 | C30: 22571 | D30: 22802 | E30: =(B30/$B$2)*$B$3 -> 33480.337
A31: 45658.09 | B31: 22748 | C31: 22381 | D31: 22802 | E31: =(B31/$B$2)*$B$3 -> 33310.475
A32: 45658.094 | B32: 22670 | C32: 22265 | D32: 22397 | E32: =(B32/$B$2)*$B$3 -> 33196.258
A33: 45658.097 | B33: 22572 | C33: 22179 | D33: 22397 | E33: =(B33/$B$2)*$B$3 -> 33052.754
A34: 45658.101 | B34: 22396 | C34: 22080 | D34: 22397 | E34: =(B34/$B$2)*$B$3 -> 32795.033
A35: 45658.104 | B35: 22295 | C35: 21968 | D35: 22302 | E35: =(B35/$B$2)*$B$3 -> 32647.136
A36: 45658.108 | B36: 22151 | C36: 21854 | D36: 22302 | E36: =(B36/$B$2)*$B$3 -> 32436.273
A37: 45658.111 | B37: 22032 | C37: 21750 | D37: 22302 | E37: =(B37/$B$2)*$B$3 -> 32262.018
A38: 45658.115 | B38: 21965 | C38: 21656 | D38: 21802 | E38: =(B38/$B$2)*$B$3 -> 32163.908
A39: 45658.118 | B39: 21855 | C39: 21567 | D39: 21802 | E39: =(B39/$B$2)*$B$3 -> 32002.833
A40: 45658.122 | B40: 21740 | C40: 21480 | D40: 21802 | E40: =(B40/$B$2)*$B$3 -> 31834.435
...

Sheet 2025-01-02
A1: Seguimiento de la demanda de energía eléctrica (MW)
A2: Demanda anual 2024 (GWh) | B2: 241811000
A3: Demanda anual 2040 (GWh) | B3: =354.09*10^6 -> 354090000
A4: Hora | B4: Real | C4: Prevista | D4: Programada | E4: Real 2040 MW | F4: Real 2040 cada h | H4: Fecha | I4: DEMANDA REAL 2040
A5: 45659 | B5: 24874 | C5: 24993 | D5: 24578 | E5: =(B5/$B$2)*$B$3 -> 36423.631 | F5: =SUM(E5:E16)/12 -> 34850.457 | H5: 45658 | I5: =F5 -> 34850.457
A6: 45659.003 | B6: 24690 | C6: 24696 | D6: 24578 | E6: =(B6/$B$2)*$B$3 -> 36154.195 | H6: 45658.042 | I6: =F17 -> 32122.175
A7: 45659.007 | B7: 24536 | C7: 24440 | D7: 24578 | E7: =(B7/$B$2)*$B$3 -> 35928.689 | H7: 45658.083 | I7: =F29 -> 30394.027
A8: 45659.01 | B8: 24219 | C8: 24225 | D8: 23798 | E8: =(B8/$B$2)*$B$3 -> 35464.498 | H8: 45658.125 | I8: =F41 -> 29481.142
A9: 45659.014 | B9: 23985 | C9: 24033 | D9: 23798 | E9: =(B9/$B$2)*$B$3 -> 35121.846 | H9: 45658.167 | I9: =F53 -> 29355.454
A10: 45659.017 | B10: 23875 | C10: 23846 | D10: 23798 | E10: =(B10/$B$2)*$B$3 -> 34960.77 | H10: 45658.208 | I10: =F65 -> 30433.93
A11: 45659.021 | B11: 23580 | C11: 23665 | D11: 23272 | E11: =(B11/$B$2)*$B$3 -> 34528.794 | H11: 45658.25 | I11: =F77 -> 34674.86
A12: 45659.024 | B12: 23505 | C12: 23491 | D12: 23272 | E12: =(B12/$B$2)*$B$3 -> 34418.97 | H12: 45658.292 | I12: =F89 -> 40256.259
A13: 45659.028 | B13: 23327 | C13: 23328 | D13: 23272 | E13: =(B13/$B$2)*$B$3 -> 34158.32 | H13: 45658.333 | I13: =F101 -> 45075.232
A14: 45659.031 | B14: 23150 | C14: 23175 | D14: 22740 | E14: =(B14/$B$2)*$B$3 -> 33899.134 | H14: 45658.375 | I14: =F113 -> 47918.83
A15: 45659.035 | B15: 23031 | C15: 23030 | D15: 22740 | E15: =(B15/$B$2)*$B$3 -> 33724.879 | H15: 45658.417 | I15: =F125 -> 48266.973
A16: 45659.038 | B16: 22824 | C16: 22892 | D16: 22740 | E16: =(B16/$B$2)*$B$3 -> 33421.764 | H16: 45658.458 | I16: =F137 -> 47331.147
A17: 45659.042 | B17: 22604 | C17: 22646 | D17: 22211 | E17: =(B17/$B$2)*$B$3 -> 33099.612 | F17: =SUM(E17:E28)/12 -> 32122.175 | H17: 45658.5 | I17: =F149 -> 46475.127
A18: 45659.045 | B18: 22402 | C18: 22519 | D18: 22211 | E18: =(B18/$B$2)*$B$3 -> 32803.819 | H18: 45658.542 | I18: =F161 -> 46375.675
A19: 45659.049 | B19: 22495 | C19: 22394 | D19: 22211 | E19: =(B19/$B$2)*$B$3 -> 32940.001 | H19: 45658.583 | I19: =F173 -> 46973.12
A20: 45659.052 | B20: 22311 | C20: 22273 | D20: 21947 | E20: =(B20/$B$2)*$B$3 -> 32670.565 | H20: 45658.625 | I20: =F185 -> 46508.196
A21: 45659.056 | B21: 22152 | C21: 22154 | D21: 21947 | E21: =(B21/$B$2)*$B$3 -> 32437.737 | H21: 45658.667 | I21: =F197 -> 46688.552
A22: 45659.059 | B22: 22022 | C22: 22037 | D22: 21947 | E22: =(B22/$B$2)*$B$3 -> 32247.375 | H22: 45658.708 | I22: =F209 -> 47970.325
A23: 45659.062 | B23: 21850 | C23: 21921 | D23: 21544 | E23: =(B23/$B$2)*$B$3 -> 31995.511 | H23: 45658.75 | I23: =F221 -> 51115.33
A24: 45659.066 | B24: 21771 | C24: 21799 | D24: 21544 | E24: =(B24/$B$2)*$B$3 -> 31879.829 | H24: 45658.792 | I24: =F233 -> 52700.585
A25: 45659.069 | B25: 21685 | C25: 21666 | D25: 21544 | E25: =(B25/$B$2)*$B$3 -> 31753.897 | H25: 45658.833 | I25: =F245 -> 53702.427
A26: 45659.073 | B26: 21411 | C26: 21520 | D26: 21244 | E26: =(B26/$B$2)*$B$3 -> 31352.672 | H26: 45658.875 | I26: =F257 -> 53199.187
A27: 45659.076 | B27: 21302 | C27: 21394 | D27: 21244 | E27: =(B27/$B$2)*$B$3 -> 31193.061 | H27: 45658.917 | I27: =F269 -> 49159.602
A28: 45659.08 | B28: 21233 | C28: 21318 | D28: 21244 | E28: =(B28/$B$2)*$B$3 -> 31092.022 | H28: 45658.958 | I28: =F281 -> 43928.909
A29: 45659.083 | B29: 21157 | C29: 21225 | D29: 20935 | E29: =(B29/$B$2)*$B$3 -> 30980.733 | F29: =SUM(E29:E40)/12 -> 30394.027
A30: 45659.087 | B30: 21036 | C30: 21207 | D30: 20935 | E30: =(B30/$B$2)*$B$3 -> 30803.55
A31: 45659.09 | B31: 21064 | C31: 21150 | D31: 20935 | E31: =(B31/$B$2)*$B$3 -> 30844.551
A32: 45659.094 | B32: 21046 | C32: 21055 | D32: 20646 | E32: =(B32/$B$2)*$B$3 -> 30818.193
A33: 45659.097 | B33: 20899 | C33: 20942 | D33: 20646 | E33: =(B33/$B$2)*$B$3 -> 30602.937
A34: 45659.101 | B34: 20844 | C34: 20831 | D34: 20646 | E34: =(B34/$B$2)*$B$3 -> 30522.4
A35: 45659.104 | B35: 20789 | C35: 20723 | D35: 20462 | E35: =(B35/$B$2)*$B$3 -> 30441.862
A36: 45659.108 | B36: 20560 | C36: 20625 | D36: 20462 | E36: =(B36/$B$2)*$B$3 -> 30106.531
A37: 45659.111 | B37: 20419 | C37: 20546 | D37: 20462 | E37: =(B37/$B$2)*$B$3 -> 29900.061
A38: 45659.115 | B38: 20481 | C38: 20486 | D38: 20364 | E38: =(B38/$B$2)*$B$3 -> 29990.849
A39: 45659.118 | B39: 20438 | C39: 20448 | D39: 20364 | E39: =(B39/$B$2)*$B$3 -> 29927.883
A40: 45659.122 | B40: 20343 | C40: 20439 | D40: 20364 | E40: =(B40/$B$2)*$B$3 -> 29788.773
...

Sheet 2025-01-03
A1: Seguimiento de la demanda de energía eléctrica (MW)
A2: Demanda anual 2024 (GWh) | B2: 241811000
A3: Demanda anual 2040 (GWh) | B3: =354.09*10^6 -> 354090000
A4: Hora | B4: Real | C4: Prevista | D4: Programada | E4: Real 2040 MW | F4: Real 2040 cada h | H4: Fecha | I4: DEMANDA REAL 2040
A5: 45660 | B5: 28116 | C5: 28586 | D5: 28132 | E5: =(B5/$B$2)*$B$3 -> 41170.974 | F5: =SUM(E5:E16)/12 -> 39786.088 | H5: 45658 | I5: =F5 -> 39786.088
A6: 45660.003 | B6: 28154 | C6: 28368 | D6: 28132 | E6: =(B6/$B$2)*$B$3 -> 41226.619 | H6: 45658.042 | I6: =F17 -> 36372.624
A7: 45660.007 | B7: 28050 | C7: 28164 | D7: 28132 | E7: =(B7/$B$2)*$B$3 -> 41074.329 | H7: 45658.083 | I7: =F29 -> 33980.038
A8: 45660.01 | B8: 27759 | C8: 27974 | D8: 27583 | E8: =(B8/$B$2)*$B$3 -> 40648.21 | H8: 45658.125 | I8: =F41 -> 32778.315
A9: 45660.014 | B9: 27495 | C9: 27788 | D9: 27583 | E9: =(B9/$B$2)*$B$3 -> 40261.628 | H9: 45658.167 | I9: =F53 -> 32358.786
A10: 45660.017 | B10: 27301 | C10: 27598 | D10: 27583 | E10: =(B10/$B$2)*$B$3 -> 39977.549 | H10: 45658.208 | I10: =F65 -> 33021.027
A11: 45660.021 | B11: 27152 | C11: 27403 | D11: 27073 | E11: =(B11/$B$2)*$B$3 -> 39759.364 | H11: 45658.25 | I11: =F77 -> 36760.792
A12: 45660.024 | B12: 26787 | C12: 27215 | D12: 27073 | E12: =(B12/$B$2)*$B$3 -> 39224.886 | H12: 45658.292 | I12: =F89 -> 41812.227
A13: 45660.028 | B13: 26610 | C13: 27041 | D13: 27073 | E13: =(B13/$B$2)*$B$3 -> 38965.7 | H13: 45658.333 | I13: =F101 -> 46297.334
A14: 45660.031 | B14: 26500 | C14: 26884 | D14: 26276 | E14: =(B14/$B$2)*$B$3 -> 38804.624 | H14: 45658.375 | I14: =F113 -> 48833.911
A15: 45660.035 | B15: 26054 | C15: 26714 | D15: 26276 | E15: =(B15/$B$2)*$B$3 -> 38151.535 | H15: 45658.417 | I15: =F125 -> 49321.41
A16: 45660.038 | B16: 26065 | C16: 26507 | D16: 26276 | E16: =(B16/$B$2)*$B$3 -> 38167.643 | H16: 45658.458 | I16: =F137 -> 48719.328
A17: 45660.042 | B17: 25808 | C17: 26129 | D17: 25654 | E17: =(B17/$B$2)*$B$3 -> 37791.311 | F17: =SUM(E17:E28)/12 -> 36372.624 | H17: 45658.5 | I17: =F149 -> 48409.745
A18: 45660.045 | B18: 25671 | C18: 25885 | D18: 25654 | E18: =(B18/$B$2)*$B$3 -> 37590.698 | H18: 45658.542 | I18: =F161 -> 48526.159
A19: 45660.049 | B19: 25382 | C19: 25681 | D19: 25654 | E19: =(B19/$B$2)*$B$3 -> 37167.508 | H19: 45658.583 | I19: =F173 -> 48482.229
A20: 45660.052 | B20: 25185 | C20: 25519 | D20: 25150 | E20: =(B20/$B$2)*$B$3 -> 36879.036 | H20: 45658.625 | I20: =F185 -> 47261.226
A21: 45660.056 | B21: 25148 | C21: 25376 | D21: 25150 | E21: =(B21/$B$2)*$B$3 -> 36824.856 | H21: 45658.667 | I21: =F197 -> 47290.024
A22: 45660.059 | B22: 24940 | C22: 25230 | D22: 25150 | E22: =(B22/$B$2)*$B$3 -> 36520.277 | H22: 45658.708 | I22: =F209 -> 48560.326
A23: 45660.062 | B23: 24683 | C23: 25081 | D23: 24595 | E23: =(B23/$B$2)*$B$3 -> 36143.945 | H23: 45658.75 | I23: =F221 -> 51258.956
A24: 45660.066 | B24: 24519 | C24: 24945 | D24: 24595 | E24: =(B24/$B$2)*$B$3 -> 35903.796 | H24: 45658.792 | I24: =F233 -> 52118.881
A25: 45660.069 | B25: 24504 | C25: 24837 | D25: 24595 | E25: =(B25/$B$2)*$B$3 -> 35881.831 | H25: 45658.833 | I25: =F245 -> 52673.983
A26: 45660.073 | B26: 24211 | C26: 24757 | D26: 24043 | E26: =(B26/$B$2)*$B$3 -> 35452.783 | H26: 45658.875 | I26: =F257 -> 51846.517
A27: 45660.076 | B27: 24082 | C27: 24663 | D27: 24043 | E27: =(B27/$B$2)*$B$3 -> 35263.885 | H27: 45658.917 | I27: =F269 -> 47934.693
A28: 45660.08 | B28: 23937 | C28: 24512 | D28: 24043 | E28: =(B28/$B$2)*$B$3 -> 35051.558 | H28: 45658.958 | I28: =F281 -> 43665.819
A29: 45660.083 | B29: 23578 | C29: 24215 | D29: 23590 | E29: =(B29/$B$2)*$B$3 -> 34525.865 | F29: =SUM(E29:E40)/12 -> 33980.038
A30: 45660.087 | B30: 23536 | C30: 24011 | D30: 23590 | E30: =(B30/$B$2)*$B$3 -> 34464.364
A31: 45660.09 | B31: 23455 | C31: 23873 | D31: 23590 | E31: =(B31/$B$2)*$B$3 -> 34345.753
A32: 45660.094 | B32: 23421 | C32: 23799 | D32: 23386 | E32: =(B32/$B$2)*$B$3 -> 34295.966
A33: 45660.097 | B33: 23332 | C33: 23750 | D33: 23386 | E33: =(B33/$B$2)*$B$3 -> 34165.641
A34: 45660.101 | B34: 23083 | C34: 23689 | D34: 23386 | E34: =(B34/$B$2)*$B$3 -> 33801.024
A35: 45660.104 | B35: 23046 | C35: 23615 | D35: 23085 | E35: =(B35/$B$2)*$B$3 -> 33746.844
A36: 45660.108 | B36: 23225 | C36: 23541 | D36: 23085 | E36: =(B36/$B$2)*$B$3 -> 34008.958
A37: 45660.111 | B37: 23121 | C37: 23481 | D37: 23085 | E37: =(B37/$B$2)*$B$3 -> 33856.669
A38: 45660.115 | B38: 22943 | C38: 23436 | D38: 22889 | E38: =(B38/$B$2)*$B$3 -> 33596.019
A39: 45660.118 | B39: 22928 | C39: 23387 | D39: 22889 | E39: =(B39/$B$2)*$B$3 -> 33574.054
A40: 45660.122 | B40: 22795 | C40: 23320 | D40: 22889 | E40: =(B40/$B$2)*$B$3 -> 33379.299
...

Sheet 2025-01-04
A1: Seguimiento de la demanda de energía eléctrica (MW)
A2: Demanda anual 2024 (GWh) | B2: 241811000
A3: Demanda anual 2040 (GWh) | B3: =354.09*10^6 -> 354090000
A4: Hora | B4: Real | C4: Prevista | D4: Programada | E4: Real 2040 MW | F4: Real 2040 cada h | H4: Fecha | I4: DEMANDA REAL 2040
A5: 45661 | B5: 28347 | C5: 28201 | D5: 27649 | E5: =(B5/$B$2)*$B$3 -> 41509.233 | F5: =SUM(E5:E16)/12 -> 40132.523 | H5: 45658 | I5: =F5 -> 40132.523
A6: 45661.003 | B6: 28438 | C6: 28024 | D6: 27649 | E6: =(B6/$B$2)*$B$3 -> 41642.487 | H6: 45658.042 | I6: =F17 -> 36619.973
A7: 45661.007 | B7: 28076 | C7: 27832 | D7: 27649 | E7: =(B7/$B$2)*$B$3 -> 41112.401 | H7: 45658.083 | I7: =F29 -> 33882.66
A8: 45661.01 | B8: 27961 | C8: 27626 | D8: 27350 | E8: =(B8/$B$2)*$B$3 -> 40944.004 | H8: 45658.125 | I8: =F41 -> 32444.815
A9: 45661.014 | B9: 27765 | C9: 27417 | D9: 27350 | E9: =(B9/$B$2)*$B$3 -> 40656.996 | H9: 45658.167 | I9: =F53 -> 31786.478
A10: 45661.017 | B10: 27535 | C10: 27218 | D10: 27350 | E10: =(B10/$B$2)*$B$3 -> 40320.201 | H10: 45658.208 | I10: =F65 -> 31884.466
A11: 45661.021 | B11: 27313 | C11: 27028 | D11: 27078 | E11: =(B11/$B$2)*$B$3 -> 39995.121 | H11: 45658.25 | I11: =F77 -> 33053.12
A12: 45661.024 | B12: 26989 | C12: 26842 | D12: 27078 | E12: =(B12/$B$2)*$B$3 -> 39520.679 | H12: 45658.292 | I12: =F89 -> 35477.921
A13: 45661.028 | B13: 26972 | C13: 26655 | D13: 27078 | E13: =(B13/$B$2)*$B$3 -> 39495.786 | H13: 45658.333 | I13: =F101 -> 38046.348
A14: 45661.031 | B14: 26800 | C14: 26467 | D14: 26327 | E14: =(B14/$B$2)*$B$3 -> 39243.922 | H14: 45658.375 | I14: =F113 -> 41192.573
A15: 45661.035 | B15: 26483 | C15: 26287 | D15: 26327 | E15: =(B15/$B$2)*$B$3 -> 38779.731 | H15: 45658.417 | I15: =F125 -> 43375.638
A16: 45661.038 | B16: 26203 | C16: 26123 | D16: 26327 | E16: =(B16/$B$2)*$B$3 -> 38369.72 | H16: 45658.458 | I16: =F137 -> 43115.964
A17: 45661.042 | B17: 25713 | C17: 25870 | D17: 25711 | E17: =(B17/$B$2)*$B$3 -> 37652.2 | F17: =SUM(E17:E28)/12 -> 36619.973 | H17: 45658.5 | I17: =F149 -> 42292.892
A18: 45661.045 | B18: 25940 | C18: 25727 | D18: 25711 | E18: =(B18/$B$2)*$B$3 -> 37984.602 | H18: 45658.542 | I18: =F161 -> 42564.89
A19: 45661.049 | B19: 25711 | C19: 25575 | D19: 25711 | E19: =(B19/$B$2)*$B$3 -> 37649.271 | H19: 45658.583 | I19: =F173 -> 43001.991
A20: 45661.052 | B20: 25521 | C20: 25415 | D20: 25113 | E20: =(B20/$B$2)*$B$3 -> 37371.05 | H20: 45658.625 | I20: =F185 -> 42610.162
A21: 45661.056 | B21: 25277 | C21: 25254 | D21: 25113 | E21: =(B21/$B$2)*$B$3 -> 37013.754 | H21: 45658.667 | I21: =F197 -> 42356.468
A22: 45661.059 | B22: 25202 | C22: 25099 | D22: 25113 | E22: =(B22/$B$2)*$B$3 -> 36903.93 | H22: 45658.708 | I22: =F209 -> 43333.173
A23: 45661.062 | B23: 25058 | C23: 24951 | D23: 24712 | E23: =(B23/$B$2)*$B$3 -> 36693.067 | H23: 45658.75 | I23: =F221 -> 45815.937
A24: 45661.066 | B24: 24954 | C24: 24806 | D24: 24712 | E24: =(B24/$B$2)*$B$3 -> 36540.777 | H24: 45658.792 | I24: =F233 -> 46935.169
A25: 45661.069 | B25: 24571 | C25: 24662 | D25: 24712 | E25: =(B25/$B$2)*$B$3 -> 35979.94 | H25: 45658.833 | I25: =F245 -> 48083.444
A26: 45661.073 | B26: 24271 | C26: 24518 | D26: 24112 | E26: =(B26/$B$2)*$B$3 -> 35540.643 | H26: 45658.875 | I26: =F257 -> 48165.447
A27: 45661.076 | B27: 23969 | C27: 24383 | D27: 24112 | E27: =(B27/$B$2)*$B$3 -> 35098.417 | H27: 45658.917 | I27: =F269 -> 44840.94
A28: 45661.08 | B28: 23910 | C28: 24261 | D28: 24112 | E28: =(B28/$B$2)*$B$3 -> 35012.021 | H28: 45658.958 | I28: =F281 -> 41235.893
A29: 45661.083 | B29: 23762 | C29: 24067 | D29: 23600 | E29: =(B29/$B$2)*$B$3 -> 34795.301 | F29: =SUM(E29:E40)/12 -> 33882.66
A30: 45661.087 | B30: 23669 | C30: 23967 | D30: 23600 | E30: =(B30/$B$2)*$B$3 -> 34659.119
A31: 45661.09 | B31: 23614 | C31: 23867 | D31: 23600 | E31: =(B31/$B$2)*$B$3 -> 34578.581
A32: 45661.094 | B32: 23322 | C32: 23766 | D32: 23102 | E32: =(B32/$B$2)*$B$3 -> 34150.998
A33: 45661.097 | B33: 23378 | C33: 23668 | D33: 23102 | E33: =(B33/$B$2)*$B$3 -> 34233
A34: 45661.101 | B34: 23164 | C34: 23574 | D34: 23102 | E34: =(B34/$B$2)*$B$3 -> 33919.635
A35: 45661.104 | B35: 23095 | C35: 23485 | D35: 22902 | E35: =(B35/$B$2)*$B$3 -> 33818.596
A36: 45661.108 | B36: 22961 | C36: 23404 | D36: 22902 | E36: =(B36/$B$2)*$B$3 -> 33622.377
A37: 45661.111 | B37: 22883 | C37: 23333 | D37: 22902 | E37: =(B37/$B$2)*$B$3 -> 33508.159
A38: 45661.115 | B38: 22669 | C38: 23273 | D38: 22602 | E38: =(B38/$B$2)*$B$3 -> 33194.793
A39: 45661.118 | B39: 22624 | C39: 23208 | D39: 22602 | E39: =(B39/$B$2)*$B$3 -> 33128.899
A40: 45661.122 | B40: 22524 | C40: 23123 | D40: 22602 | E40: =(B40/$B$2)*$B$3 -> 32982.466
...

Sheet 2025-01-05
A1: Seguimiento de la demanda de energía eléctrica (MW)
A2: Demanda anual 2024 (GWh) | B2: 241811000
A3: Demanda anual 2040 (GWh) | B3: =354.09*10^6 -> 354090000
A4: Hora | B4: Real | C4: Prevista | D4: Programada | E4: Real 2040 MW | F4: Real 2040 cada h | H4: Fecha | I4: DEMANDA REAL 2040
A5: 45662 | B5: 26852 | C5: 26805 | D5: 26331 | E5: =(B5/$B$2)*$B$3 -> 39320.067 | F5: =SUM(E5:E16)/12 -> 37817.303 | H5: 45658 | I5: =F5 -> 37817.303
A6: 45662.003 | B6: 26758 | C6: 26572 | D6: 26331 | E6: =(B6/$B$2)*$B$3 -> 39182.42 | H6: 45658.042 | I6: =F17 -> 34690.724
A7: 45662.007 | B7: 26475 | C7: 26407 | D7: 26331 | E7: =(B7/$B$2)*$B$3 -> 38768.016 | H7: 45658.083 | I7: =F29 -> 32328.645
A8: 45662.01 | B8: 26364 | C8: 26310 | D8: 25720 | E8: =(B8/$B$2)*$B$3 -> 38605.476 | H8: 45658.125 | I8: =F41 -> 30755.959
A9: 45662.014 | B9: 26301 | C9: 26215 | D9: 25720 | E9: =(B9/$B$2)*$B$3 -> 38513.224 | H9: 45658.167 | I9: =F53 -> 30186.703
A10: 45662.017 | B10: 26060 | C10: 26053 | D10: 25720 | E10: =(B10/$B$2)*$B$3 -> 38160.321 | H10: 45658.208 | I10: =F65 -> 30030.508
A11: 45662.021 | B11: 25614 | C11: 25826 | D11: 25141 | E11: =(B11/$B$2)*$B$3 -> 37507.232 | H11: 45658.25 | I11: =F77 -> 30869.079
A12: 45662.024 | B12: 25614 | C12: 25567 | D12: 25141 | E12: =(B12/$B$2)*$B$3 -> 37507.232 | H12: 45658.292 | I12: =F89 -> 32280.322
A13: 45662.028 | B13: 25318 | C13: 25311 | D13: 25141 | E13: =(B13/$B$2)*$B$3 -> 37073.792 | H13: 45658.333 | I13: =F101 -> 34008.348
A14: 45662.031 | B14: 25071 | C14: 25057 | D14: 24621 | E14: =(B14/$B$2)*$B$3 -> 36712.103 | H14: 45658.375 | I14: =F113 -> 36799.231
A15: 45662.035 | B15: 24765 | C15: 24834 | D15: 24621 | E15: =(B15/$B$2)*$B$3 -> 36264.02 | H15: 45658.417 | I15: =F125 -> 39399.506
A16: 45662.038 | B16: 24717 | C16: 24673 | D16: 24621 | E16: =(B16/$B$2)*$B$3 -> 36193.732 | H16: 45658.458 | I16: =F137 -> 40318.249
A17: 45662.042 | B17: 24598 | C17: 24473 | D17: 23982 | E17: =(B17/$B$2)*$B$3 -> 36019.477 | F17: =SUM(E17:E28)/12 -> 34690.724 | H17: 45658.5 | I17: =F149 -> 40871.764
A18: 45662.045 | B18: 24443 | C18: 24384 | D18: 23982 | E18: =(B18/$B$2)*$B$3 -> 35792.507 | H18: 45658.542 | I18: =F161 -> 42057.501
A19: 45662.049 | B19: 24385 | C19: 24255 | D19: 23982 | E19: =(B19/$B$2)*$B$3 -> 35707.576 | H19: 45658.583 | I19: =F173 -> 42609.308
A20: 45662.052 | B20: 24099 | C20: 24085 | D20: 23777 | E20: =(B20/$B$2)*$B$3 -> 35288.779 | H20: 45658.625 | I20: =F185 -> 41810.884
A21: 45662.056 | B21: 23923 | C21: 23900 | D21: 23777 | E21: =(B21/$B$2)*$B$3 -> 35031.058 | H21: 45658.667 | I21: =F197 -> 41618.448
A22: 45662.059 | B22: 23882 | C22: 23725 | D22: 23777 | E22: =(B22/$B$2)*$B$3 -> 34971.02 | H22: 45658.708 | I22: =F209 -> 41893.253
A23: 45662.062 | B23: 23479 | C23: 23559 | D23: 23109 | E23: =(B23/$B$2)*$B$3 -> 34380.897 | H23: 45658.75 | I23: =F221 -> 43390.159
A24: 45662.066 | B24: 23340 | C24: 23398 | D24: 23109 | E24: =(B24/$B$2)*$B$3 -> 34177.356 | H24: 45658.792 | I24: =F233 -> 43761.61
A25: 45662.069 | B25: 23328 | C25: 23238 | D25: 23109 | E25: =(B25/$B$2)*$B$3 -> 34159.784 | H25: 45658.833 | I25: =F245 -> 44708.052
A26: 45662.073 | B26: 23143 | C26: 23078 | D26: 22911 | E26: =(B26/$B$2)*$B$3 -> 33888.884 | H26: 45658.875 | I26: =F257 -> 45047.654
A27: 45662.076 | B27: 22948 | C27: 22925 | D27: 22911 | E27: =(B27/$B$2)*$B$3 -> 33603.34 | H27: 45658.917 | I27: =F269 -> 42770.994
A28: 45662.08 | B28: 22719 | C28: 22784 | D28: 22911 | E28: =(B28/$B$2)*$B$3 -> 33268.01 | H28: 45658.958 | I28: =F281 -> 39551.796
A29: 45662.083 | B29: 22723 | C29: 22577 | D29: 22382 | E29: =(B29/$B$2)*$B$3 -> 33273.867 | F29: =SUM(E29:E40)/12 -> 32328.645
A30: 45662.087 | B30: 22495 | C30: 22457 | D30: 22382 | E30: =(B30/$B$2)*$B$3 -> 32940.001
A31: 45662.09 | B31: 22479 | C31: 22343 | D31: 22382 | E31: =(B31/$B$2)*$B$3 -> 32916.572
A32: 45662.094 | B32: 22286 | C32: 22234 | D32: 22178 | E32: =(B32/$B$2)*$B$3 -> 32633.957
A33: 45662.097 | B33: 21970 | C33: 22133 | D33: 22178 | E33: =(B33/$B$2)*$B$3 -> 32171.23
A34: 45662.101 | B34: 22157 | C34: 22046 | D34: 22178 | E34: =(B34/$B$2)*$B$3 -> 32445.059
A35: 45662.104 | B35: 22116 | C35: 21973 | D35: 21979 | E35: =(B35/$B$2)*$B$3 -> 32385.022
A36: 45662.108 | B36: 22032 | C36: 21892 | D36: 21979 | E36: =(B36/$B$2)*$B$3 -> 32262.018
A37: 45662.111 | B37: 21921 | C37: 21782 | D37: 21979 | E37: =(B37/$B$2)*$B$3 -> 32099.478
A38: 45662.115 | B38: 21619 | C38: 21645 | D38: 21374 | E38: =(B38/$B$2)*$B$3 -> 31657.252
A39: 45662.118 | B39: 21481 | C39: 21512 | D39: 21374 | E39: =(B39/$B$2)*$B$3 -> 31455.175
A40: 45662.122 | B40: 21651 | C40: 21417 | D40: 21374 | E40: =(B40/$B$2)*$B$3 -> 31704.11
...

Sheet 2025-01-06
A1: Seguimiento de la demanda de energía eléctrica (MW)
A2: Demanda anual 2024 (GWh) | B2: 241811000
A3: Demanda anual 2040 (GWh) | B3: =354.09*10^6 -> 354090000
A4: Hora | B4: Real | C4: Prevista | D4: Programada | E4: Real 2040 MW | F4: Real 2040 cada h | H4: Fecha | I4: DEMANDA REAL 2040
A5: 45663 | B5: 25821 | C5: 26165 | D5: 25199 | E5: =(B5/$B$2)*$B$3 -> 37810.347 | F5: =SUM(E5:E16)/12 -> 36219.602 | H5: 45658 | I5: =F5 -> 36219.602
A6: 45663.003 | B6: 25554 | C6: 25926 | D6: 25199 | E6: =(B6/$B$2)*$B$3 -> 37419.372 | H6: 45658.042 | I6: =F17 -> 33268.132
A7: 45663.007 | B7: 25353 | C7: 25770 | D7: 25199 | E7: =(B7/$B$2)*$B$3 -> 37125.043 | H7: 45658.083 | I7: =F29 -> 30961.819
A8: 45663.01 | B8: 25169 | C8: 25699 | D8: 24888 | E8: =(B8/$B$2)*$B$3 -> 36855.607 | H8: 45658.125 | I8: =F41 -> 29575.835
A9: 45663.014 | B9: 25100 | C9: 25663 | D9: 24888 | E9: =(B9/$B$2)*$B$3 -> 36754.569 | H9: 45658.167 | I9: =F53 -> 28907.981
A10: 45663.017 | B10: 24773 | C10: 25615 | D10: 24888 | E10: =(B10/$B$2)*$B$3 -> 36275.734 | H10: 45658.208 | I10: =F65 -> 29049.044
A11: 45663.021 | B11: 24558 | C11: 25554 | D11: 24712 | E11: =(B11/$B$2)*$B$3 -> 35960.904 | H11: 45658.25 | I11: =F77 -> 29901.159
A12: 45663.024 | B12: 24377 | C12: 25515 | D12: 24712 | E12: =(B12/$B$2)*$B$3 -> 35695.861 | H12: 45658.292 | I12: =F89 -> 31238.943
A13: 45663.028 | B13: 24242 | C13: 25534 | D13: 24712 | E13: =(B13/$B$2)*$B$3 -> 35498.177 | H13: 45658.333 | I13: =F101 -> 32818.34
A14: 45663.031 | B14: 24261 | C14: 25608 | D14: 23880 | E14: =(B14/$B$2)*$B$3 -> 35526 | H14: 45658.375 | I14: =F113 -> 35466.938
A15: 45663.035 | B15: 23919 | C15: 25617 | D15: 23880 | E15: =(B15/$B$2)*$B$3 -> 35025.2 | H15: 45658.417 | I15: =F125 -> 37671.358
A16: 45663.038 | B16: 23689 | C16: 25436 | D16: 23880 | E16: =(B16/$B$2)*$B$3 -> 34688.405 | H16: 45658.458 | I16: =F137 -> 38726.771
A17: 45663.042 | B17: 23465 | C17: 25003 | D17: 23295 | E17: =(B17/$B$2)*$B$3 -> 34360.397 | F17: =SUM(E17:E28)/12 -> 33268.132 | H17: 45658.5 | I17: =F149 -> 38751.787
A18: 45663.045 | B18: 23307 | C18: 24608 | D18: 23295 | E18: =(B18/$B$2)*$B$3 -> 34129.033 | H18: 45658.542 | I18: =F161 -> 39212.805
A19: 45663.049 | B19: 23329 | C19: 24352 | D19: 23295 | E19: =(B19/$B$2)*$B$3 -> 34161.248 | H19: 45658.583 | I19: =F173 -> 38616.825
A20: 45663.052 | B20: 23134 | C20: 24234 | D20: 22909 | E20: =(B20/$B$2)*$B$3 -> 33875.705 | H20: 45658.625 | I20: =F185 -> 37059.636
A21: 45663.056 | B21: 22908 | C21: 24160 | D21: 22909 | E21: =(B21/$B$2)*$B$3 -> 33544.767 | H21: 45658.667 | I21: =F197 -> 36801.549
A22: 45663.059 | B22: 22867 | C22: 24036 | D22: 22909 | E22: =(B22/$B$2)*$B$3 -> 33484.73 | H22: 45658.708 | I22: =F209 -> 38101.138
A23: 45663.062 | B23: 22775 | C23: 23863 | D23: 22544 | E23: =(B23/$B$2)*$B$3 -> 33350.012 | H23: 45658.75 | I23: =F221 -> 41555.97
A24: 45663.066 | B24: 22512 | C24: 23705 | D24: 22544 | E24: =(B24/$B$2)*$B$3 -> 32964.894 | H24: 45658.792 | I24: =F233 -> 43596.873
A25: 45663.069 | B25: 22171 | C25: 23625 | D25: 22544 | E25: =(B25/$B$2)*$B$3 -> 32465.559 | H25: 45658.833 | I25: =F245 -> 45171.999
A26: 45663.073 | B26: 22246 | C26: 23624 | D26: 22238 | E26: =(B26/$B$2)*$B$3 -> 32575.384 | H26: 45658.875 | I26: =F257 -> 45455.102
A27: 45663.076 | B27: 21974 | C27: 23540 | D27: 22238 | E27: =(B27/$B$2)*$B$3 -> 32177.087 | H27: 45658.917 | I27: =F269 -> 43418.958
A28: 45663.08 | B28: 21941 | C28: 23212 | D28: 22238 | E28: =(B28/$B$2)*$B$3 -> 32128.765 | H28: 45658.958 | I28: =F281 -> 39461.862
A29: 45663.083 | B29: 21764 | C29: 22579 | D29: 21458 | E29: =(B29/$B$2)*$B$3 -> 31869.579 | F29: =SUM(E29:E40)/12 -> 30961.819
A30: 45663.087 | B30: 21708 | C30: 22006 | D30: 21458 | E30: =(B30/$B$2)*$B$3 -> 31787.577
A31: 45663.09 | B31: 21592 | C31: 21678 | D31: 21458 | E31: =(B31/$B$2)*$B$3 -> 31617.715
A32: 45663.094 | B32: 21622 | C32: 21595 | D32: 21256 | E32: =(B32/$B$2)*$B$3 -> 31661.645
A33: 45663.097 | B33: 21305 | C33: 21607 | D33: 21256 | E33: =(B33/$B$2)*$B$3 -> 31197.454
A34: 45663.101 | B34: 21170 | C34: 21565 | D34: 21256 | E34: =(B34/$B$2)*$B$3 -> 30999.77
A35: 45663.104 | B35: 21170 | C35: 21467 | D35: 21054 | E35: =(B35/$B$2)*$B$3 -> 30999.77
A36: 45663.108 | B36: 20994 | C36: 21365 | D36: 21054 | E36: =(B36/$B$2)*$B$3 -> 30742.048
A37: 45663.111 | B37: 20803 | C37: 21308 | D37: 21054 | E37: =(B37/$B$2)*$B$3 -> 30462.362
A38: 45663.115 | B38: 20694 | C38: 21295 | D38: 20747 | E38: =(B38/$B$2)*$B$3 -> 30302.751
A39: 45663.118 | B39: 20435 | C39: 21268 | D39: 20747 | E39: =(B39/$B$2)*$B$3 -> 29923.49
A40: 45663.122 | B40: 20472 | C40: 21167 | D40: 20747 | E40: =(B40/$B$2)*$B$3 -> 29977.67
...

Sheet 2025-01-07
A1: Seguimiento de la demanda de energía eléctrica (MW)
A2: Demanda anual 2024 (GWh) | B2: 241811000
A3: Demanda anual 2040 (GWh) | B3: =354.09*10^6 -> 354090000
A4: Hora | B4: Real | C4: Prevista | D4: Programada | E4: Real 2040 MW | F4: Real 2040 cada h | H4: Fecha | I4: DEMANDA REAL 2040
A5: 45664 | B5: 25503 | C5: 25639 | D5: 24947 | E5: =(B5/$B$2)*$B$3 -> 37344.692 | F5: =SUM(E5:E16)/12 -> 36097.331 | H5: 45658 | I5: =F5 -> 36097.331
A6: 45664.003 | B6: 25310 | C6: 25118 | D6: 24947 | E6: =(B6/$B$2)*$B$3 -> 37062.077 | H6: 45658.042 | I6: =F17 -> 33390.769
A7: 45664.007 | B7: 25304 | C7: 24744 | D7: 24947 | E7: =(B7/$B$2)*$B$3 -> 37053.291 | H7: 45658.083 | I7: =F29 -> 31733.275
A8: 45664.01 | B8: 25167 | C8: 24515 | D8: 24647 | E8: =(B8/$B$2)*$B$3 -> 36852.678 | H8: 45658.125 | I8: =F41 -> 31123.627
A9: 45664.014 | B9: 24652 | C9: 24348 | D9: 24647 | E9: =(B9/$B$2)*$B$3 -> 36098.551 | H9: 45658.167 | I9: =F53 -> 31285.923
A10: 45664.017 | B10: 24841 | C10: 24159 | D10: 24647 | E10: =(B10/$B$2)*$B$3 -> 36375.308 | H10: 45658.208 | I10: =F65 -> 32448.598
A11: 45664.021 | B11: 24639 | C11: 23947 | D11: 23948 | E11: =(B11/$B$2)*$B$3 -> 36079.515 | H11: 45658.25 | I11: =F77 -> 37355.308
A12: 45664.024 | B12: 24285 | C12: 23739 | D12: 23948 | E12: =(B12/$B$2)*$B$3 -> 35561.143 | H12: 45658.292 | I12: =F89 -> 43789.92
A13: 45664.028 | B13: 24108 | C13: 23564 | D13: 23948 | E13: =(B13/$B$2)*$B$3 -> 35301.958 | H13: 45658.333 | I13: =F101 -> 49300.665
A14: 45664.031 | B14: 24149 | C14: 23422 | D14: 23545 | E14: =(B14/$B$2)*$B$3 -> 35361.995 | H14: 45658.375 | I14: =F113 -> 51292.88
A15: 45664.035 | B15: 23933 | C15: 23281 | D15: 23545 | E15: =(B15/$B$2)*$B$3 -> 35045.701 | H15: 45658.417 | I15: =F125 -> 51119.845
A16: 45664.038 | B16: 23923 | C16: 23109 | D16: 23545 | E16: =(B16/$B$2)*$B$3 -> 35031.058 | H16: 45658.458 | I16: =F137 -> 49963.76
A17: 45664.042 | B17: 23571 | C17: 22794 | D17: 23289 | E17: =(B17/$B$2)*$B$3 -> 34515.615 | F17: =SUM(E17:E28)/12 -> 33390.769 | H17: 45658.5 | I17: =F149 -> 48926.286
A18: 45664.045 | B18: 23569 | C18: 22596 | D18: 23289 | E18: =(B18/$B$2)*$B$3 -> 34512.686 | H18: 45658.542 | I18: =F161 -> 49335.809
A19: 45664.049 | B19: 23360 | C19: 22435 | D19: 23289 | E19: =(B19/$B$2)*$B$3 -> 34206.642 | H19: 45658.583 | I19: =F173 -> 49598.167
A20: 45664.052 | B20: 23110 | C20: 22311 | D20: 22890 | E20: =(B20/$B$2)*$B$3 -> 33840.561 | H20: 45658.625 | I20: =F185 -> 49494.322
A21: 45664.056 | B21: 22995 | C21: 22208 | D21: 22890 | E21: =(B21/$B$2)*$B$3 -> 33672.164 | H21: 45658.667 | I21: =F197 -> 49968.763
A22: 45664.059 | B22: 22808 | C22: 22109 | D22: 22890 | E22: =(B22/$B$2)*$B$3 -> 33398.335 | H22: 45658.708 | I22: =F209 -> 51621.377
A23: 45664.062 | B23: 22643 | C23: 22014 | D23: 22533 | E23: =(B23/$B$2)*$B$3 -> 33156.721 | H23: 45658.75 | I23: =F221 -> 54613.97
A24: 45664.066 | B24: 22475 | C24: 21913 | D24: 22533 | E24: =(B24/$B$2)*$B$3 -> 32910.714 | H24: 45658.792 | I24: =F233 -> 56245.35
A25: 45664.069 | B25: 22465 | C25: 21796 | D25: 22533 | E25: =(B25/$B$2)*$B$3 -> 32896.071 | H25: 45658.833 | I25: =F245 -> 57703.086
A26: 45664.073 | B26: 22325 | C26: 21663 | D26: 21967 | E26: =(B26/$B$2)*$B$3 -> 32691.066 | H26: 45658.875 | I26: =F257 -> 56430.466
A27: 45664.076 | B27: 22210 | C27: 21568 | D27: 21967 | E27: =(B27/$B$2)*$B$3 -> 32522.668 | H27: 45658.917 | I27: =F269 -> 50537.044
A28: 45664.08 | B28: 22103 | C28: 21566 | D28: 21967 | E28: =(B28/$B$2)*$B$3 -> 32365.985 | H28: 45658.958 | I28: =F281 -> 44561.864
A29: 45664.083 | B29: 22185 | C29: 21573 | D29: 21926 | E29: =(B29/$B$2)*$B$3 -> 32486.06 | F29: =SUM(E29:E40)/12 -> 31733.275
A30: 45664.087 | B30: 22087 | C30: 21667 | D30: 21926 | E30: =(B30/$B$2)*$B$3 -> 32342.556
A31: 45664.09 | B31: 21852 | C31: 21673 | D31: 21926 | E31: =(B31/$B$2)*$B$3 -> 31998.44
A32: 45664.094 | B32: 21778 | C32: 21593 | D32: 21605 | E32: =(B32/$B$2)*$B$3 -> 31890.08
A33: 45664.097 | B33: 21627 | C33: 21483 | D33: 21605 | E33: =(B33/$B$2)*$B$3 -> 31668.966
A34: 45664.101 | B34: 21684 | C34: 21401 | D34: 21605 | E34: =(B34/$B$2)*$B$3 -> 31752.433
A35: 45664.104 | B35: 21523 | C35: 21348 | D35: 21506 | E35: =(B35/$B$2)*$B$3 -> 31516.677
A36: 45664.108 | B36: 21588 | C36: 21302 | D36: 21506 | E36: =(B36/$B$2)*$B$3 -> 31611.858
A37: 45664.111 | B37: 21646 | C37: 21243 | D37: 21506 | E37: =(B37/$B$2)*$B$3 -> 31696.789
A38: 45664.115 | B38: 21390 | C38: 21170 | D38: 21200 | E38: =(B38/$B$2)*$B$3 -> 31321.921
A39: 45664.118 | B39: 21340 | C39: 21110 | D39: 21200 | E39: =(B39/$B$2)*$B$3 -> 31248.705
A40: 45664.122 | B40: 21351 | C40: 21088 | D40: 21200 | E40: =(B40/$B$2)*$B$3 -> 31264.813
...
